Workbook
Name 今日: 設定表!$B$4
Name 警察局名稱: 設定表!$B$16
Name 分局名稱: 設定表!$B$17
Name 派出所名稱: 設定表!$B$18
Name 派出所英文: 設定表!$B$19
Name 員警姓名清單: 設定表!$B$24:$B$83
Name 毒調率目標: 設定表!$B$87
Name 新進閾值: 設定表!$B$88
Name 老案閾值: 設定表!$B$89
Name 案件容量警示: 設定表!$B$90
Name 案件容量上限: 設定表!$B$91
Name 毒調逾期天數: 設定表!$B$92
Name 歷史保留月數: 設定表!$B$93
Name 案類代碼清單: 設定表!$A$98:$A$158
Name 案類名稱清單: 設定表!$B$98:$B$158
Name 案類分類清單: 設定表!$C$98:$C$158
Name 納入全般清單: 設定表!$D$98:$D$158
Name 違規項目清單: 設定表!$A$168:$A$177
Name 婦幼件數: 設定表!$B$181
Name 協尋件數: 設定表!$B$182
Name 偵辦進度清單: 設定表!$A$189:$A$192
Name 案件狀況清單: 設定表!$A$195:$A$198
Name 發生管轄清單: 設定表!$A$201:$A$202
Name 查獲管轄清單: 設定表!$A$205:$A$206
Name 性別清單: 設定表!$A$209:$A$210
Name 通緝清單: 設定表!$A$213:$A$214
Name 毒品管制情形清單: 設定表!$A$217:$A$222
Name 發展中進度清單: 設定表!$A$225:$A$227
Name 是否在職清單: 設定表!$A$230:$A$231
Name 績效類別清單: 設定表!$A$234:$A$236
Name 線索來源清單: 設定表!$A$239:$A$244
Name 重大性清單: 設定表!$A$247:$A$249

Sheet 首頁_操作說明
A1: 🏛 派出所綜合管制系統 v2
A2: KKEVIN-LIN-2026-V2.0 ｜ 全台通用 ｜ 無巨集 ｜ 一檔搞定刑案/毒調/交通/績效/歷史
A4: ★ 本月一句話
A5: ="系統健檢 ✓ 通過 ｜ 案件 " & IFERROR(COUNTA(Tbl案件[編號]), 0) & "/" & 案件容量上限 & " ｜ 健康狀態：穩定運作"
A7: 👤 我是… | D7: 📍 我要去…（點擊一鍵跳轉）
A8: ▸ 第一次用 | D8: → 設定表（先填派出所名稱與員警名冊）
A9: ▸ 員警／承辦人 | D9: → 案件資料庫（登錄案件）
A10: ▸ 所長 | D10: → 管制總覽（看全所狀態）
A11: ▸ 督導官 | D11: → 長官5分鐘報告（A4 一頁列印交付）
A12: ▸ 上級機關承辦 | D12: → 對上級機關上呈（公文體例三層格式）
A14: 📦 5 分鐘上手三步驟
A15: ① | B15: 填設定表 | C15: 派出所名稱、警察局、分局、員警名冊 — 一次設定終身受用
A16: ② | B16: 案件資料庫試打 | C16: 到「案件資料庫」第一列填試打資料，下拉選單會逐欄帶您
A17: ③ | B17: 回管制總覽 | C17: 看九宮格 KPI 是否點亮，狀態燈正常即代表系統運作健康
A19: =" © 林錦瑞 ｜ KKEVIN-LIN-2026-V2.1 ｜ 今日:" & TEXT(今日, "[$-zh-TW]yyyy/mm/dd")

Sheet 管制總覽
A1: 📊 管制總覽（V4 九宮格 Small Multiples）
A2: =" "&警察局名稱&" · "&分局名稱&" · "&派出所名稱&" ｜ 中華民國 "&(YEAR(今日)-1911)&" 年 "&TEXT(MONTH(今日),"00")&" 月 ｜ 製表："&TEXT(今日,"e/mm/dd")
A4: =IF(COUNTIF(S50:S58,"*紅*")>0,"🚨 全所有 "&COUNTIF(S50:S58,"*紅*")&" 項紅燈需立即處理，請查看下方警示摘要",IF(COUNTIF(S50:S58,"*黃*")>0,"⚠ 全所狀態尚可，"&COUNTIF(S50:S58,"*黃*")&" 項黃燈需關注，建議排入週會檢討","✓ 全所狀態良好：9 大 KPI 全綠燈通過"))
A6: 📊 9 KPI 九宮格 ｜ 每格：當期現值 + 狀態燈 + 近 12 月走勢
A8: 01 全般破獲率 | E8: =IF(A9>=0.85,"● 綠",IF(A9>=0.7,"⚠ 黃","● 紅")) | G8: 02 竊盜破獲率 | K8: =IF(G9>=0.8,"● 綠",IF(G9>=0.6,"⚠ 黃","● 紅")) | M8: 03 詐欺破獲率 | Q8: =IF(M9>=0.6,"● 綠",IF(M9>=0.4,"⚠ 黃","● 紅"))
A9: =IFERROR(COUNTIFS(Tbl案件[查獲管轄],"本轄",Tbl案件[是否破獲],"是",Tbl案件[歸屬年度],(YEAR(今日)-1911))/COUNTIFS(Tbl案件[發生管轄],"本轄",Tbl案件[歸屬年度],(YEAR(今日)-1911),Tbl案件[計入發生數],"是"),0) | G9: =IFERROR(COUNTIFS(Tbl案件[案類分類],"竊盜",Tbl案件[查獲管轄],"本轄",Tbl案件[是否破獲],"是",Tbl案件[歸屬年度],(YEAR(今日)-1911))/COUNTIFS(Tbl案件[案類分類],"竊盜",Tbl案件[發生管轄],"本轄",Tbl案件[歸屬年度],(YEAR(今日)-1911),Tbl案件[計入發生數],"是"),0) | M9: =IFERROR(COUNTIFS(Tbl案件[案類分類],"詐欺",Tbl案件[查獲管轄],"本轄",Tbl案件[是否破獲],"是",Tbl案件[歸屬年度],(YEAR(今日)-1911))/COUNTIFS(Tbl案件[案類分類],"詐欺",Tbl案件[發生管轄],"本轄",Tbl案件[歸屬年度],(YEAR(今日)-1911),Tbl案件[計入發生數],"是"),0)
A10: 目標 ≥ 85% ｜ 黃燈 70-85% ｜ 紅燈 < 70% | G10: 目標 ≥ 80% ｜ 黃燈 60-80% ｜ 紅燈 < 60% | M10: 目標 ≥ 60% ｜ 黃燈 40-60% ｜ 紅燈 < 40%
A11: =AR50 | G11: =AR51 | M11: =AR52
A13: 04 毒調率 | E13: =IF(IFERROR(SUM(Tbl毒調[是否到驗])/COUNTA(Tbl毒調[姓名]),0)>=毒調率目標,"● 綠",IF(IFERROR(SUM(Tbl毒調[是否到驗])/COUNTA(Tbl毒調[姓名]),0)>=(毒調率目標-0.1),"⚠ 黃","● 紅")) | G13: 05 未到驗人口 | K13: =IF(IFERROR(SUM(Tbl毒調[候選旗標]),0)<=5,"● 綠",IF(IFERROR(SUM(Tbl毒調[候選旗標]),0)<=10,"⚠ 黃","● 紅")) | M13: 06 未破案件 | Q13: =IF(M14<=5,"● 綠",IF(M14<=10,"⚠ 黃","● 紅"))
A14: =IFERROR(SUM(Tbl毒調[是否到驗])/COUNTA(Tbl毒調[姓名]),0) | G14: =IFERROR(COUNTA(Tbl毒調[姓名])-SUM(Tbl毒調[是否到驗])-COUNTIF(Tbl毒調[狀態燈],"*結束*"),0) | M14: =IFERROR(COUNTIFS(Tbl案件[案件狀況],"尚未偵破",Tbl案件[發生管轄],"本轄",Tbl案件[歸屬年度],(YEAR(今日)-1911),Tbl案件[計入發生數],"是"),0)
A15: 目標 ≥ 60% ｜ 黃燈 50-60% ｜ 紅燈 < 50% | G15: 目標 < 5 人 ｜ 黃燈 5-10 ｜ 紅燈 > 10（值越小越好） | M15: 目標 ≤ 5 件 ｜ 黃燈 5-10 件 ｜ 紅燈 > 10 件（值越小越好）
A16: =AR53 | G16: =AR54 | M16: =AR55
A18: 07 交通達成率 | E18: =IF(A19>=0.8,"● 綠",IF(A19>=0.6,"⚠ 黃","● 紅")) | G18: 08 酒駕取締 | K18: =IF(G19>=3,"● 綠",IF(G19>=1,"⚠ 黃","● 紅")) | M18: 09 闖紅燈取締 | Q18: =IF(M19>=5,"● 綠",IF(M19>=1,"⚠ 黃","● 紅"))
A19: =IFERROR(交通績效管制!E8,0) | G19: =IFERROR(COUNTIF(Tbl交通[違規項目],"*酒駕*"),0) | M19: =IFERROR(COUNTIF(Tbl交通[違規項目],"*闖紅燈*"),0)
A20: 目標 ≥ 80% ｜ 黃燈 60-80% ｜ 紅燈 < 60% | G20: 目標 ≥ 3 件 ｜ 黃燈 1-3 件 ｜ 紅燈 0 件 | M20: 目標 ≥ 5 件 ｜ 黃燈 1-5 件 ｜ 紅燈 0 件
A21: =AR56 | G21: =AR57 | M21: =AR58
A23: ⚠ 警示摘要（公式自動聚合 9 KPI 燈號）
A24: ● 紅燈總數 | G24: ⚠ 黃燈總數 | M24: ● 綠燈總數
A25: =COUNTIF(S50:S58,"*紅*") | G25: =COUNTIF(S50:S58,"*黃*") | M25: =COUNTIF(S50:S58,"*綠*")
A26: 需立即處理 | G26: 建議週會檢討 | M26: 持續維持
A28: ="© KKEVIN-LIN-2026-V2.0 ｜ 資料源：Tbl案件 + Tbl交通 + Tbl歷史 ｜ 製表："&TEXT(今日,"e/mm/dd")&" ｜ 下次重算：開檔自動"
R49: [helper] KPI | S49: 燈 | T49: 近 12 月資料 (T..AE) → | AF49: block 字元 (AF..AQ) → | AR49: sparkline 字串
R50: 01 全般破獲率 | S50: =E8 | T50: =IFERROR(INDEX(Tbl歷史,MAX(1,ROWS(Tbl歷史)-11+0),5),"") | U50: =IFERROR(INDEX(Tbl歷史,MAX(1,ROWS(Tbl歷史)-11+1),5),"") | V50: =IFERROR(INDEX(Tbl歷史,MAX(1,ROWS(Tbl歷史)-11+2),5),"") | W50: =IFERROR(INDEX(Tbl歷史,MAX(1,ROWS(Tbl歷史)-11+3),5),"") | X50: =IFERROR(INDEX(Tbl歷史,MAX(1,ROWS(Tbl歷史)-11+4),5),"") | Y50: =IFERROR(INDEX(Tbl歷史,MAX(1,ROWS(Tbl歷史)-11+5),5),"") | Z50: =IFERROR(INDEX(Tbl歷史,MAX(1,ROWS(Tbl歷史)-11+6),5),"") | AA50: =IFERROR(INDEX(Tbl歷史,MAX(1,ROWS(Tbl歷史)-11+7),5),"") | AB50: =IFERROR(INDEX(Tbl歷史,MAX(1,ROWS(Tbl歷史)-11+8),5),"") | AC50: =IFERROR(INDEX(Tbl歷史,MAX(1,ROWS(Tbl歷史)-11+9),5),"") | AD50: =IFERROR(INDEX(Tbl歷史,MAX(1,ROWS(Tbl歷史)-11+10),5),"") | AE50: =IFERROR(INDEX(Tbl歷史,MAX(1,ROWS(Tbl歷史)-11+11),5),"") | AF50: =IF(OR(NOT(ISNUMBER(T50)),MAX($T50:$AE50)=MIN($T50:$AE50)),IF(ISNUMBER(T50),"▄",""),CHOOSE(1+MIN(7,MAX(0,ROUND((T50-MIN($T50:$AE50))/(MAX($T50:$AE50)-MIN($T50:$AE50))*7,0))),"▁","▂","▃","▄","▅","▆","▇","█")) | AG50: =IF(OR(NOT(ISNUMBER(U50)),MAX($T50:$AE50)=MIN($T50:$AE50)),IF(ISNUMBER(U50),"▄",""),CHOOSE(1+MIN(7,MAX(0,ROUND((U50-MIN($T50:$AE50))/(MAX($T50:$AE50)-MIN($T50:$AE50))*7,0))),"▁","▂","▃","▄","▅","▆","▇","█")) | AH50: =IF(OR(NOT(ISNUMBER(V50)),MAX($T50:$AE50)=MIN($T50:$AE50)),IF(ISNUMBER(V50),"▄",""),CHOOSE(1+MIN(7,MAX(0,ROUND((V50-MIN($T50:$AE50))/(MAX($T50:$AE50)-MIN($T50:$AE50))*7,0))),"▁","▂","▃","▄","▅","▆","▇","█")) | AI50: =IF(OR(NOT(ISNUMBER(W50)),MAX($T50:$AE50)=MIN($T50:$AE50)),IF(ISNUMBER(W50),"▄",""),CHOOSE(1+MIN(7,MAX(0,ROUND((W50-MIN($T50:$AE50))/(MAX($T50:$AE50)-MIN($T50:$AE50))*7,0))),"▁","▂","▃","▄","▅","▆","▇","█")) | AJ50: =IF(OR(NOT(ISNUMBER(X50)),MAX($T50:$AE50)=MIN($T50:$AE50)),IF(ISNUMBER(X50),"▄",""),CHOOSE(1+MIN(7,MAX(0,ROUND((X50-MIN($T50:$AE50))/(MAX($T50:$AE50)-MIN($T50:$AE50))*7,0))),"▁","▂","▃","▄","▅","▆","▇","█")) | AK50: =IF(OR(NOT(ISNUMBER(Y50)),MAX($T50:$AE50)=MIN($T50:$AE50)),IF(ISNUMBER(Y50),"▄",""),CHOOSE(1+MIN(7,MAX(0,ROUND((Y50-MIN($T50:$AE50))/(MAX($T50:$AE50)-MIN($T50:$AE50))*7,0))),"▁","▂","▃","▄","▅","▆","▇","█")) | AL50: =IF(OR(NOT(ISNUMBER(Z50)),MAX($T50:$AE50)=MIN($T50:$AE50)),IF(ISNUMBER(Z50),"▄",""),CHOOSE(1+MIN(7,MAX(0,ROUND((Z50-MIN($T50:$AE50))/(MAX($T50:$AE50)-MIN($T50:$AE50))*7,0))),"▁","▂","▃","▄","▅","▆","▇","█")) | AM50: =IF(OR(NOT(ISNUMBER(AA50)),MAX($T50:$AE50)=MIN($T50:$AE50)),IF(ISNUMBER(AA50),"▄",""),CHOOSE(1+MIN(7,MAX(0,ROUND((AA50-MIN($T50:$AE50))/(MAX($T50:$AE50)-MIN($T50:$AE50))*7,0))),"▁","▂","▃","▄","▅","▆","▇","█")) | ... AQ50: =IF(OR(NOT(ISNUMBER(AE50)),MAX($T50:$AE50)=MIN($T50:$AE50)),IF(ISNUMBER(AE50),"▄",""),CHOOSE(1+MIN(7,MAX(0,ROUND((AE50-MIN($T50:$AE50))/(MAX($T50:$AE50)-MIN($T50:$AE50))*7,0))),"▁","▂","▃","▄","▅","▆","▇","█")) | AR50: =IFERROR(CONCAT($AF50:$AQ50),"")
R51: 02 竊盜破獲率 | S51: =K8 | T51: =IFERROR(INDEX(Tbl歷史,MAX(1,ROWS(Tbl歷史)-11+0),6),"") | U51: =IFERROR(INDEX(Tbl歷史,MAX(1,ROWS(Tbl歷史)-11+1),6),"") | V51: =IFERROR(INDEX(Tbl歷史,MAX(1,ROWS(Tbl歷史)-11+2),6),"") | W51: =IFERROR(INDEX(Tbl歷史,MAX(1,ROWS(Tbl歷史)-11+3),6),"") | X51: =IFERROR(INDEX(Tbl歷史,MAX(1,ROWS(Tbl歷史)-11+4),6),"") | Y51: =IFERROR(INDEX(Tbl歷史,MAX(1,ROWS(Tbl歷史)-11+5),6),"") | Z51: =IFERROR(INDEX(Tbl歷史,MAX(1,ROWS(Tbl歷史)-11+6),6),"") | AA51: =IFERROR(INDEX(Tbl歷史,MAX(1,ROWS(Tbl歷史)-11+7),6),"") | AB51: =IFERROR(INDEX(Tbl歷史,MAX(1,ROWS(Tbl歷史)-11+8),6),"") | AC51: =IFERROR(INDEX(Tbl歷史,MAX(1,ROWS(Tbl歷史)-11+9),6),"") | AD51: =IFERROR(INDEX(Tbl歷史,MAX(1,ROWS(Tbl歷史)-11+10),6),"") | AE51: =IFERROR(INDEX(Tbl歷史,MAX(1,ROWS(Tbl歷史)-11+11),6),"") | AF51: =IF(OR(NOT(ISNUMBER(T51)),MAX($T51:$AE51)=MIN($T51:$AE51)),IF(ISNUMBER(T51),"▄",""),CHOOSE(1+MIN(7,MAX(0,ROUND((T51-MIN($T51:$AE51))/(MAX($T51:$AE51)-MIN($T51:$AE51))*7,0))),"▁","▂","▃","▄","▅","▆","▇","█")) | AG51: =IF(OR(NOT(ISNUMBER(U51)),MAX($T51:$AE51)=MIN($T51:$AE51)),IF(ISNUMBER(U51),"▄",""),CHOOSE(1+MIN(7,MAX(0,ROUND((U51-MIN($T51:$AE51))/(MAX($T51:$AE51)-MIN($T51:$AE51))*7,0))),"▁","▂","▃","▄","▅","▆","▇","█")) | AH51: =IF(OR(NOT(ISNUMBER(V51)),MAX($T51:$AE51)=MIN($T51:$AE51)),IF(ISNUMBER(V51),"▄",""),CHOOSE(1+MIN(7,MAX(0,ROUND((V51-MIN($T51:$AE51))/(MAX($T51:$AE51)-MIN($T51:$AE51))*7,0))),"▁","▂","▃","▄","▅","▆","▇","█")) | AI51: =IF(OR(NOT(ISNUMBER(W51)),MAX($T51:$AE51)=MIN($T51:$AE51)),IF(ISNUMBER(W51),"▄",""),CHOOSE(1+MIN(7,MAX(0,ROUND((W51-MIN($T51:$AE51))/(MAX($T51:$AE51)-MIN($T51:$AE51))*7,0))),"▁","▂","▃","▄","▅","▆","▇","█")) | AJ51: =IF(OR(NOT(ISNUMBER(X51)),MAX($T51:$AE51)=MIN($T51:$AE51)),IF(ISNUMBER(X51),"▄",""),CHOOSE(1+MIN(7,MAX(0,ROUND((X51-MIN($T51:$AE51))/(MAX($T51:$AE51)-MIN($T51:$AE51))*7,0))),"▁","▂","▃","▄","▅","▆","▇","█")) | AK51: =IF(OR(NOT(ISNUMBER(Y51)),MAX($T51:$AE51)=MIN($T51:$AE51)),IF(ISNUMBER(Y51),"▄",""),CHOOSE(1+MIN(7,MAX(0,ROUND((Y51-MIN($T51:$AE51))/(MAX($T51:$AE51)-MIN($T51:$AE51))*7,0))),"▁","▂","▃","▄","▅","▆","▇","█")) | AL51: =IF(OR(NOT(ISNUMBER(Z51)),MAX($T51:$AE51)=MIN($T51:$AE51)),IF(ISNUMBER(Z51),"▄",""),CHOOSE(1+MIN(7,MAX(0,ROUND((Z51-MIN($T51:$AE51))/(MAX($T51:$AE51)-MIN($T51:$AE51))*7,0))),"▁","▂","▃","▄","▅","▆","▇","█")) | AM51: =IF(OR(NOT(ISNUMBER(AA51)),MAX($T51:$AE51)=MIN($T51:$AE51)),IF(ISNUMBER(AA51),"▄",""),CHOOSE(1+MIN(7,MAX(0,ROUND((AA51-MIN($T51:$AE51))/(MAX($T51:$AE51)-MIN($T51:$AE51))*7,0))),"▁","▂","▃","▄","▅","▆","▇","█")) | ... AQ51: =IF(OR(NOT(ISNUMBER(AE51)),MAX($T51:$AE51)=MIN($T51:$AE51)),IF(ISNUMBER(AE51),"▄",""),CHOOSE(1+MIN(7,MAX(0,ROUND((AE51-MIN($T51:$AE51))/(MAX($T51:$AE51)-MIN($T51:$AE51))*7,0))),"▁","▂","▃","▄","▅","▆","▇","█")) | AR51: =IFERROR(CONCAT($AF51:$AQ51),"")
R52: 03 詐欺破獲率 | S52: =Q8 | T52: =IFERROR(INDEX(Tbl歷史,MAX(1,ROWS(Tbl歷史)-11+0),7),"") | U52: =IFERROR(INDEX(Tbl歷史,MAX(1,ROWS(Tbl歷史)-11+1),7),"") | V52: =IFERROR(INDEX(Tbl歷史,MAX(1,ROWS(Tbl歷史)-11+2),7),"") | W52: =IFERROR(INDEX(Tbl歷史,MAX(1,ROWS(Tbl歷史)-11+3),7),"") | X52: =IFERROR(INDEX(Tbl歷史,MAX(1,ROWS(Tbl歷史)-11+4),7),"") | Y52: =IFERROR(INDEX(Tbl歷史,MAX(1,ROWS(Tbl歷史)-11+5),7),"") | Z52: =IFERROR(INDEX(Tbl歷史,MAX(1,ROWS(Tbl歷史)-11+6),7),"") | AA52: =IFERROR(INDEX(Tbl歷史,MAX(1,ROWS(Tbl歷史)-11+7),7),"") | AB52: =IFERROR(INDEX(Tbl歷史,MAX(1,ROWS(Tbl歷史)-11+8),7),"") | AC52: =IFERROR(INDEX(Tbl歷史,MAX(1,ROWS(Tbl歷史)-11+9),7),"") | AD52: =IFERROR(INDEX(Tbl歷史,MAX(1,ROWS(Tbl歷史)-11+10),7),"") | AE52: =IFERROR(INDEX(Tbl歷史,MAX(1,ROWS(Tbl歷史)-11+11),7),"") | AF52: =IF(OR(NOT(ISNUMBER(T52)),MAX($T52:$AE52)=MIN($T52:$AE52)),IF(ISNUMBER(T52),"▄",""),CHOOSE(1+MIN(7,MAX(0,ROUND((T52-MIN($T52:$AE52))/(MAX($T52:$AE52)-MIN($T52:$AE52))*7,0))),"▁","▂","▃","▄","▅","▆","▇","█")) | AG52: =IF(OR(NOT(ISNUMBER(U52)),MAX($T52:$AE52)=MIN($T52:$AE52)),IF(ISNUMBER(U52),"▄",""),CHOOSE(1+MIN(7,MAX(0,ROUND((U52-MIN($T52:$AE52))/(MAX($T52:$AE52)-MIN($T52:$AE52))*7,0))),"▁","▂","▃","▄","▅","▆","▇","█")) | AH52: =IF(OR(NOT(ISNUMBER(V52)),MAX($T52:$AE52)=MIN($T52:$AE52)),IF(ISNUMBER(V52),"▄",""),CHOOSE(1+MIN(7,MAX(0,ROUND((V52-MIN($T52:$AE52))/(MAX($T52:$AE52)-MIN($T52:$AE52))*7,0))),"▁","▂","▃","▄","▅","▆","▇","█")) | AI52: =IF(OR(NOT(ISNUMBER(W52)),MAX($T52:$AE52)=MIN($T52:$AE52)),IF(ISNUMBER(W52),"▄",""),CHOOSE(1+MIN(7,MAX(0,ROUND((W52-MIN($T52:$AE52))/(MAX($T52:$AE52)-MIN($T52:$AE52))*7,0))),"▁","▂","▃","▄","▅","▆","▇","█")) | AJ52: =IF(OR(NOT(ISNUMBER(X52)),MAX($T52:$AE52)=MIN($T52:$AE52)),IF(ISNUMBER(X52),"▄",""),CHOOSE(1+MIN(7,MAX(0,ROUND((X52-MIN($T52:$AE52))/(MAX($T52:$AE52)-MIN($T52:$AE52))*7,0))),"▁","▂","▃","▄","▅","▆","▇","█")) | AK52: =IF(OR(NOT(ISNUMBER(Y52)),MAX($T52:$AE52)=MIN($T52:$AE52)),IF(ISNUMBER(Y52),"▄",""),CHOOSE(1+MIN(7,MAX(0,ROUND((Y52-MIN($T52:$AE52))/(MAX($T52:$AE52)-MIN($T52:$AE52))*7,0))),"▁","▂","▃","▄","▅","▆","▇","█")) | AL52: =IF(OR(NOT(ISNUMBER(Z52)),MAX($T52:$AE52)=MIN($T52:$AE52)),IF(ISNUMBER(Z52),"▄",""),CHOOSE(1+MIN(7,MAX(0,ROUND((Z52-MIN($T52:$AE52))/(MAX($T52:$AE52)-MIN($T52:$AE52))*7,0))),"▁","▂","▃","▄","▅","▆","▇","█")) | AM52: =IF(OR(NOT(ISNUMBER(AA52)),MAX($T52:$AE52)=MIN($T52:$AE52)),IF(ISNUMBER(AA52),"▄",""),CHOOSE(1+MIN(7,MAX(0,ROUND((AA52-MIN($T52:$AE52))/(MAX($T52:$AE52)-MIN($T52:$AE52))*7,0))),"▁","▂","▃","▄","▅","▆","▇","█")) | ... AQ52: =IF(OR(NOT(ISNUMBER(AE52)),MAX($T52:$AE52)=MIN($T52:$AE52)),IF(ISNUMBER(AE52),"▄",""),CHOOSE(1+MIN(7,MAX(0,ROUND((AE52-MIN($T52:$AE52))/(MAX($T52:$AE52)-MIN($T52:$AE52))*7,0))),"▁","▂","▃","▄","▅","▆","▇","█")) | AR52: =IFERROR(CONCAT($AF52:$AQ52),"")
R53: 04 毒調率 | S53: =E13 | T53: =IFERROR(INDEX(Tbl歷史,MAX(1,ROWS(Tbl歷史)-11+0),10),"") | U53: =IFERROR(INDEX(Tbl歷史,MAX(1,ROWS(Tbl歷史)-11+1),10),"") | V53: =IFERROR(INDEX(Tbl歷史,MAX(1,ROWS(Tbl歷史)-11+2),10),"") | W53: =IFERROR(INDEX(Tbl歷史,MAX(1,ROWS(Tbl歷史)-11+3),10),"") | X53: =IFERROR(INDEX(Tbl歷史,MAX(1,ROWS(Tbl歷史)-11+4),10),"") | Y53: =IFERROR(INDEX(Tbl歷史,MAX(1,ROWS(Tbl歷史)-11+5),10),"") | Z53: =IFERROR(INDEX(Tbl歷史,MAX(1,ROWS(Tbl歷史)-11+6),10),"") | AA53: =IFERROR(INDEX(Tbl歷史,MAX(1,ROWS(Tbl歷史)-11+7),10),"") | AB53: =IFERROR(INDEX(Tbl歷史,MAX(1,ROWS(Tbl歷史)-11+8),10),"") | AC53: =IFERROR(INDEX(Tbl歷史,MAX(1,ROWS(Tbl歷史)-11+9),10),"") | AD53: =IFERROR(INDEX(Tbl歷史,MAX(1,ROWS(Tbl歷史)-11+10),10),"") | AE53: =IFERROR(INDEX(Tbl歷史,MAX(1,ROWS(Tbl歷史)-11+11),10),"") | AF53: =IF(OR(NOT(ISNUMBER(T53)),MAX($T53:$AE53)=MIN($T53:$AE53)),IF(ISNUMBER(T53),"▄",""),CHOOSE(1+MIN(7,MAX(0,ROUND((T53-MIN($T53:$AE53))/(MAX($T53:$AE53)-MIN($T53:$AE53))*7,0))),"▁","▂","▃","▄","▅","▆","▇","█")) | AG53: =IF(OR(NOT(ISNUMBER(U53)),MAX($T53:$AE53)=MIN($T53:$AE53)),IF(ISNUMBER(U53),"▄",""),CHOOSE(1+MIN(7,MAX(0,ROUND((U53-MIN($T53:$AE53))/(MAX($T53:$AE53)-MIN($T53:$AE53))*7,0))),"▁","▂","▃","▄","▅","▆","▇","█")) | AH53: =IF(OR(NOT(ISNUMBER(V53)),MAX($T53:$AE53)=MIN($T53:$AE53)),IF(ISNUMBER(V53),"▄",""),CHOOSE(1+MIN(7,MAX(0,ROUND((V53-MIN($T53:$AE53))/(MAX($T53:$AE53)-MIN($T53:$AE53))*7,0))),"▁","▂","▃","▄","▅","▆","▇","█")) | AI53: =IF(OR(NOT(ISNUMBER(W53)),MAX($T53:$AE53)=MIN($T53:$AE53)),IF(ISNUMBER(W53),"▄",""),CHOOSE(1+MIN(7,MAX(0,ROUND((W53-MIN($T53:$AE53))/(MAX($T53:$AE53)-MIN($T53:$AE53))*7,0))),"▁","▂","▃","▄","▅","▆","▇","█")) | AJ53: =IF(OR(NOT(ISNUMBER(X53)),MAX($T53:$AE53)=MIN($T53:$AE53)),IF(ISNUMBER(X53),"▄",""),CHOOSE(1+MIN(7,MAX(0,ROUND((X53-MIN($T53:$AE53))/(MAX($T53:$AE53)-MIN($T53:$AE53))*7,0))),"▁","▂","▃","▄","▅","▆","▇","█")) | AK53: =IF(OR(NOT(ISNUMBER(Y53)),MAX($T53:$AE53)=MIN($T53:$AE53)),IF(ISNUMBER(Y53),"▄",""),CHOOSE(1+MIN(7,MAX(0,ROUND((Y53-MIN($T53:$AE53))/(MAX($T53:$AE53)-MIN($T53:$AE53))*7,0))),"▁","▂","▃","▄","▅","▆","▇","█")) | AL53: =IF(OR(NOT(ISNUMBER(Z53)),MAX($T53:$AE53)=MIN($T53:$AE53)),IF(ISNUMBER(Z53),"▄",""),CHOOSE(1+MIN(7,MAX(0,ROUND((Z53-MIN($T53:$AE53))/(MAX($T53:$AE53)-MIN($T53:$AE53))*7,0))),"▁","▂","▃","▄","▅","▆","▇","█")) | AM53: =IF(OR(NOT(ISNUMBER(AA53)),MAX($T53:$AE53)=MIN($T53:$AE53)),IF(ISNUMBER(AA53),"▄",""),CHOOSE(1+MIN(7,MAX(0,ROUND((AA53-MIN($T53:$AE53))/(MAX($T53:$AE53)-MIN($T53:$AE53))*7,0))),"▁","▂","▃","▄","▅","▆","▇","█")) | ... AQ53: =IF(OR(NOT(ISNUMBER(AE53)),MAX($T53:$AE53)=MIN($T53:$AE53)),IF(ISNUMBER(AE53),"▄",""),CHOOSE(1+MIN(7,MAX(0,ROUND((AE53-MIN($T53:$AE53))/(MAX($T53:$AE53)-MIN($T53:$AE53))*7,0))),"▁","▂","▃","▄","▅","▆","▇","█")) | AR53: =IFERROR(CONCAT($AF53:$AQ53),"")
R54: 05 未到驗人口 | S54: =K13 | T54: =IFERROR(INDEX(Tbl歷史,MAX(1,ROWS(Tbl歷史)-11+0),11),"") | U54: =IFERROR(INDEX(Tbl歷史,MAX(1,ROWS(Tbl歷史)-11+1),11),"") | V54: =IFERROR(INDEX(Tbl歷史,MAX(1,ROWS(Tbl歷史)-11+2),11),"") | W54: =IFERROR(INDEX(Tbl歷史,MAX(1,ROWS(Tbl歷史)-11+3),11),"") | X54: =IFERROR(INDEX(Tbl歷史,MAX(1,ROWS(Tbl歷史)-11+4),11),"") | Y54: =IFERROR(INDEX(Tbl歷史,MAX(1,ROWS(Tbl歷史)-11+5),11),"") | Z54: =IFERROR(INDEX(Tbl歷史,MAX(1,ROWS(Tbl歷史)-11+6),11),"") | AA54: =IFERROR(INDEX(Tbl歷史,MAX(1,ROWS(Tbl歷史)-11+7),11),"") | AB54: =IFERROR(INDEX(Tbl歷史,MAX(1,ROWS(Tbl歷史)-11+8),11),"") | AC54: =IFERROR(INDEX(Tbl歷史,MAX(1,ROWS(Tbl歷史)-11+9),11),"") | AD54: =IFERROR(INDEX(Tbl歷史,MAX(1,ROWS(Tbl歷史)-11+10),11),"") | AE54: =IFERROR(INDEX(Tbl歷史,MAX(1,ROWS(Tbl歷史)-11+11),11),"") | AF54: =IF(OR(NOT(ISNUMBER(T54)),MAX($T54:$AE54)=MIN($T54:$AE54)),IF(ISNUMBER(T54),"▄",""),CHOOSE(1+MIN(7,MAX(0,ROUND((T54-MIN($T54:$AE54))/(MAX($T54:$AE54)-MIN($T54:$AE54))*7,0))),"▁","▂","▃","▄","▅","▆","▇","█")) | AG54: =IF(OR(NOT(ISNUMBER(U54)),MAX($T54:$AE54)=MIN($T54:$AE54)),IF(ISNUMBER(U54),"▄",""),CHOOSE(1+MIN(7,MAX(0,ROUND((U54-MIN($T54:$AE54))/(MAX($T54:$AE54)-MIN($T54:$AE54))*7,0))),"▁","▂","▃","▄","▅","▆","▇","█")) | AH54: =IF(OR(NOT(ISNUMBER(V54)),MAX($T54:$AE54)=MIN($T54:$AE54)),IF(ISNUMBER(V54),"▄",""),CHOOSE(1+MIN(7,MAX(0,ROUND((V54-MIN($T54:$AE54))/(MAX($T54:$AE54)-MIN($T54:$AE54))*7,0))),"▁","▂","▃","▄","▅","▆","▇","█")) | AI54: =IF(OR(NOT(ISNUMBER(W54)),MAX($T54:$AE54)=MIN($T54:$AE54)),IF(ISNUMBER(W54),"▄",""),CHOOSE(1+MIN(7,MAX(0,ROUND((W54-MIN($T54:$AE54))/(MAX($T54:$AE54)-MIN($T54:$AE54))*7,0))),"▁","▂","▃","▄","▅","▆","▇","█")) | AJ54: =IF(OR(NOT(ISNUMBER(X54)),MAX($T54:$AE54)=MIN($T54:$AE54)),IF(ISNUMBER(X54),"▄",""),CHOOSE(1+MIN(7,MAX(0,ROUND((X54-MIN($T54:$AE54))/(MAX($T54:$AE54)-MIN($T54:$AE54))*7,0))),"▁","▂","▃","▄","▅","▆","▇","█")) | AK54: =IF(OR(NOT(ISNUMBER(Y54)),MAX($T54:$AE54)=MIN($T54:$AE54)),IF(ISNUMBER(Y54),"▄",""),CHOOSE(1+MIN(7,MAX(0,ROUND((Y54-MIN($T54:$AE54))/(MAX($T54:$AE54)-MIN($T54:$AE54))*7,0))),"▁","▂","▃","▄","▅","▆","▇","█")) | AL54: =IF(OR(NOT(ISNUMBER(Z54)),MAX($T54:$AE54)=MIN($T54:$AE54)),IF(ISNUMBER(Z54),"▄",""),CHOOSE(1+MIN(7,MAX(0,ROUND((Z54-MIN($T54:$AE54))/(MAX($T54:$AE54)-MIN($T54:$AE54))*7,0))),"▁","▂","▃","▄","▅","▆","▇","█")) | AM54: =IF(OR(NOT(ISNUMBER(AA54)),MAX($T54:$AE54)=MIN($T54:$AE54)),IF(ISNUMBER(AA54),"▄",""),CHOOSE(1+MIN(7,MAX(0,ROUND((AA54-MIN($T54:$AE54))/(MAX($T54:$AE54)-MIN($T54:$AE54))*7,0))),"▁","▂","▃","▄","▅","▆","▇","█")) | ... AQ54: =IF(OR(NOT(ISNUMBER(AE54)),MAX($T54:$AE54)=MIN($T54:$AE54)),IF(ISNUMBER(AE54),"▄",""),CHOOSE(1+MIN(7,MAX(0,ROUND((AE54-MIN($T54:$AE54))/(MAX($T54:$AE54)-MIN($T54:$AE54))*7,0))),"▁","▂","▃","▄","▅","▆","▇","█")) | AR54: =IFERROR(CONCAT($AF54:$AQ54),"")
R55: 06 未破案件 | S55: =Q13 | T55: =IFERROR(INDEX(Tbl歷史,MAX(1,ROWS(Tbl歷史)-11+0),3),"") | U55: =IFERROR(INDEX(Tbl歷史,MAX(1,ROWS(Tbl歷史)-11+1),3),"") | V55: =IFERROR(INDEX(Tbl歷史,MAX(1,ROWS(Tbl歷史)-11+2),3),"") | W55: =IFERROR(INDEX(Tbl歷史,MAX(1,ROWS(Tbl歷史)-11+3),3),"") | X55: =IFERROR(INDEX(Tbl歷史,MAX(1,ROWS(Tbl歷史)-11+4),3),"") | Y55: =IFERROR(INDEX(Tbl歷史,MAX(1,ROWS(Tbl歷史)-11+5),3),"") | Z55: =IFERROR(INDEX(Tbl歷史,MAX(1,ROWS(Tbl歷史)-11+6),3),"") | AA55: =IFERROR(INDEX(Tbl歷史,MAX(1,ROWS(Tbl歷史)-11+7),3),"") | AB55: =IFERROR(INDEX(Tbl歷史,MAX(1,ROWS(Tbl歷史)-11+8),3),"") | AC55: =IFERROR(INDEX(Tbl歷史,MAX(1,ROWS(Tbl歷史)-11+9),3),"") | AD55: =IFERROR(INDEX(Tbl歷史,MAX(1,ROWS(Tbl歷史)-11+10),3),"") | AE55: =IFERROR(INDEX(Tbl歷史,MAX(1,ROWS(Tbl歷史)-11+11),3),"") | AF55: =IF(OR(NOT(ISNUMBER(T55)),MAX($T55:$AE55)=MIN($T55:$AE55)),IF(ISNUMBER(T55),"▄",""),CHOOSE(1+MIN(7,MAX(0,ROUND((T55-MIN($T55:$AE55))/(MAX($T55:$AE55)-MIN($T55:$AE55))*7,0))),"▁","▂","▃","▄","▅","▆","▇","█")) | AG55: =IF(OR(NOT(ISNUMBER(U55)),MAX($T55:$AE55)=MIN($T55:$AE55)),IF(ISNUMBER(U55),"▄",""),CHOOSE(1+MIN(7,MAX(0,ROUND((U55-MIN($T55:$AE55))/(MAX($T55:$AE55)-MIN($T55:$AE55))*7,0))),"▁","▂","▃","▄","▅","▆","▇","█")) | AH55: =IF(OR(NOT(ISNUMBER(V55)),MAX($T55:$AE55)=MIN($T55:$AE55)),IF(ISNUMBER(V55),"▄",""),CHOOSE(1+MIN(7,MAX(0,ROUND((V55-MIN($T55:$AE55))/(MAX($T55:$AE55)-MIN($T55:$AE55))*7,0))),"▁","▂","▃","▄","▅","▆","▇","█")) | AI55: =IF(OR(NOT(ISNUMBER(W55)),MAX($T55:$AE55)=MIN($T55:$AE55)),IF(ISNUMBER(W55),"▄",""),CHOOSE(1+MIN(7,MAX(0,ROUND((W55-MIN($T55:$AE55))/(MAX($T55:$AE55)-MIN($T55:$AE55))*7,0))),"▁","▂","▃","▄","▅","▆","▇","█")) | AJ55: =IF(OR(NOT(ISNUMBER(X55)),MAX($T55:$AE55)=MIN($T55:$AE55)),IF(ISNUMBER(X55),"▄",""),CHOOSE(1+MIN(7,MAX(0,ROUND((X55-MIN($T55:$AE55))/(MAX($T55:$AE55)-MIN($T55:$AE55))*7,0))),"▁","▂","▃","▄","▅","▆","▇","█")) | AK55: =IF(OR(NOT(ISNUMBER(Y55)),MAX($T55:$AE55)=MIN($T55:$AE55)),IF(ISNUMBER(Y55),"▄",""),CHOOSE(1+MIN(7,MAX(0,ROUND((Y55-MIN($T55:$AE55))/(MAX($T55:$AE55)-MIN($T55:$AE55))*7,0))),"▁","▂","▃","▄","▅","▆","▇","█")) | AL55: =IF(OR(NOT(ISNUMBER(Z55)),MAX($T55:$AE55)=MIN($T55:$AE55)),IF(ISNUMBER(Z55),"▄",""),CHOOSE(1+MIN(7,MAX(0,ROUND((Z55-MIN($T55:$AE55))/(MAX($T55:$AE55)-MIN($T55:$AE55))*7,0))),"▁","▂","▃","▄","▅","▆","▇","█")) | AM55: =IF(OR(NOT(ISNUMBER(AA55)),MAX($T55:$AE55)=MIN($T55:$AE55)),IF(ISNUMBER(AA55),"▄",""),CHOOSE(1+MIN(7,MAX(0,ROUND((AA55-MIN($T55:$AE55))/(MAX($T55:$AE55)-MIN($T55:$AE55))*7,0))),"▁","▂","▃","▄","▅","▆","▇","█")) | ... AQ55: =IF(OR(NOT(ISNUMBER(AE55)),MAX($T55:$AE55)=MIN($T55:$AE55)),IF(ISNUMBER(AE55),"▄",""),CHOOSE(1+MIN(7,MAX(0,ROUND((AE55-MIN($T55:$AE55))/(MAX($T55:$AE55)-MIN($T55:$AE55))*7,0))),"▁","▂","▃","▄","▅","▆","▇","█")) | AR55: =IFERROR(CONCAT($AF55:$AQ55),"")
R56: 07 交通達成率 | S56: =E18 | T56: =IFERROR(INDEX(Tbl歷史,MAX(1,ROWS(Tbl歷史)-11+0),12),"") | U56: =IFERROR(INDEX(Tbl歷史,MAX(1,ROWS(Tbl歷史)-11+1),12),"") | V56: =IFERROR(INDEX(Tbl歷史,MAX(1,ROWS(Tbl歷史)-11+2),12),"") | W56: =IFERROR(INDEX(Tbl歷史,MAX(1,ROWS(Tbl歷史)-11+3),12),"") | X56: =IFERROR(INDEX(Tbl歷史,MAX(1,ROWS(Tbl歷史)-11+4),12),"") | Y56: =IFERROR(INDEX(Tbl歷史,MAX(1,ROWS(Tbl歷史)-11+5),12),"") | Z56: =IFERROR(INDEX(Tbl歷史,MAX(1,ROWS(Tbl歷史)-11+6),12),"") | AA56: =IFERROR(INDEX(Tbl歷史,MAX(1,ROWS(Tbl歷史)-11+7),12),"") | AB56: =IFERROR(INDEX(Tbl歷史,MAX(1,ROWS(Tbl歷史)-11+8),12),"") | AC56: =IFERROR(INDEX(Tbl歷史,MAX(1,ROWS(Tbl歷史)-11+9),12),"") | AD56: =IFERROR(INDEX(Tbl歷史,MAX(1,ROWS(Tbl歷史)-11+10),12),"") | AE56: =IFERROR(INDEX(Tbl歷史,MAX(1,ROWS(Tbl歷史)-11+11),12),"") | AF56: =IF(OR(NOT(ISNUMBER(T56)),MAX($T56:$AE56)=MIN($T56:$AE56)),IF(ISNUMBER(T56),"▄",""),CHOOSE(1+MIN(7,MAX(0,ROUND((T56-MIN($T56:$AE56))/(MAX($T56:$AE56)-MIN($T56:$AE56))*7,0))),"▁","▂","▃","▄","▅","▆","▇","█")) | AG56: =IF(OR(NOT(ISNUMBER(U56)),MAX($T56:$AE56)=MIN($T56:$AE56)),IF(ISNUMBER(U56),"▄",""),CHOOSE(1+MIN(7,MAX(0,ROUND((U56-MIN($T56:$AE56))/(MAX($T56:$AE56)-MIN($T56:$AE56))*7,0))),"▁","▂","▃","▄","▅","▆","▇","█")) | AH56: =IF(OR(NOT(ISNUMBER(V56)),MAX($T56:$AE56)=MIN($T56:$AE56)),IF(ISNUMBER(V56),"▄",""),CHOOSE(1+MIN(7,MAX(0,ROUND((V56-MIN($T56:$AE56))/(MAX($T56:$AE56)-MIN($T56:$AE56))*7,0))),"▁","▂","▃","▄","▅","▆","▇","█")) | AI56: =IF(OR(NOT(ISNUMBER(W56)),MAX($T56:$AE56)=MIN($T56:$AE56)),IF(ISNUMBER(W56),"▄",""),CHOOSE(1+MIN(7,MAX(0,ROUND((W56-MIN($T56:$AE56))/(MAX($T56:$AE56)-MIN($T56:$AE56))*7,0))),"▁","▂","▃","▄","▅","▆","▇","█")) | AJ56: =IF(OR(NOT(ISNUMBER(X56)),MAX($T56:$AE56)=MIN($T56:$AE56)),IF(ISNUMBER(X56),"▄",""),CHOOSE(1+MIN(7,MAX(0,ROUND((X56-MIN($T56:$AE56))/(MAX($T56:$AE56)-MIN($T56:$AE56))*7,0))),"▁","▂","▃","▄","▅","▆","▇","█")) | AK56: =IF(OR(NOT(ISNUMBER(Y56)),MAX($T56:$AE56)=MIN($T56:$AE56)),IF(ISNUMBER(Y56),"▄",""),CHOOSE(1+MIN(7,MAX(0,ROUND((Y56-MIN($T56:$AE56))/(MAX($T56:$AE56)-MIN($T56:$AE56))*7,0))),"▁","▂","▃","▄","▅","▆","▇","█")) | AL56: =IF(OR(NOT(ISNUMBER(Z56)),MAX($T56:$AE56)=MIN($T56:$AE56)),IF(ISNUMBER(Z56),"▄",""),CHOOSE(1+MIN(7,MAX(0,ROUND((Z56-MIN($T56:$AE56))/(MAX($T56:$AE56)-MIN($T56:$AE56))*7,0))),"▁","▂","▃","▄","▅","▆","▇","█")) | AM56: =IF(OR(NOT(ISNUMBER(AA56)),MAX($T56:$AE56)=MIN($T56:$AE56)),IF(ISNUMBER(AA56),"▄",""),CHOOSE(1+MIN(7,MAX(0,ROUND((AA56-MIN($T56:$AE56))/(MAX($T56:$AE56)-MIN($T56:$AE56))*7,0))),"▁","▂","▃","▄","▅","▆","▇","█")) | ... AQ56: =IF(OR(NOT(ISNUMBER(AE56)),MAX($T56:$AE56)=MIN($T56:$AE56)),IF(ISNUMBER(AE56),"▄",""),CHOOSE(1+MIN(7,MAX(0,ROUND((AE56-MIN($T56:$AE56))/(MAX($T56:$AE56)-MIN($T56:$AE56))*7,0))),"▁","▂","▃","▄","▅","▆","▇","█")) | AR56: =IFERROR(CONCAT($AF56:$AQ56),"")
R57: 08 酒駕取締 | S57: =K18 | AR57: ="─ 待擴充 ─"
R58: 09 闖紅燈取締 | S58: =Q18 | AR58: ="─ 待擴充 ─"

Sheet 全般刑案管制情形分析
A1: ⚖ 全般刑案管制情形分析
A2: =派出所英文&" · "&警察局名稱&" · "&分局名稱&" · "&派出所名稱&" ｜ REPORT DATE: "&TEXT(今日,"yyyy/mm/dd")
A3: ="統計區間：中華民國 "&(YEAR(今日)-1911)&" 年 01/01 ~ "&TEXT(今日,"mm/dd")&" ｜ 同期對照：中華民國 "&(YEAR(今日)-1912)&" 年同期間"
A5: 壹 全般刑案總覽
A6: 🎯 本所統計·破獲率 查獲管轄=本轄 ÷ 發生管轄=本轄 | D6: 📊 發生件數 發生管轄=本轄 | F6: ✓ 破獲件數（本所） 查獲管轄=本轄
A7: =IFERROR(COUNTIFS(Tbl案件[查獲管轄],"本轄",Tbl案件[是否破獲],"是",Tbl案件[歸屬年度],(YEAR(今日)-1911))/COUNTIFS(Tbl案件[發生管轄],"本轄",Tbl案件[歸屬年度],(YEAR(今日)-1911),Tbl案件[計入發生數],"是"),0) | D7: =IFERROR(COUNTIFS(Tbl案件[發生管轄],"本轄",Tbl案件[歸屬年度],(YEAR(今日)-1911),Tbl案件[計入發生數],"是"),0) | F7: =IFERROR(COUNTIFS(Tbl案件[查獲管轄],"本轄",Tbl案件[是否破獲],"是",Tbl案件[歸屬年度],(YEAR(今日)-1911)),0)
A8: 本所破獲率： | C8: =REPT("█",MIN(20,ROUND(IFERROR(COUNTIFS(Tbl案件[查獲管轄],"本轄",Tbl案件[是否破獲],"是",Tbl案件[歸屬年度],(YEAR(今日)-1911))/COUNTIFS(Tbl案件[發生管轄],"本轄",Tbl案件[歸屬年度],(YEAR(今日)-1911),Tbl案件[計入發生數],"是"),0)*20,0)))&" "&TEXT(IFERROR(COUNTIFS(Tbl案件[查獲管轄],"本轄",Tbl案件[是否破獲],"是",Tbl案件[歸屬年度],(YEAR(今日)-1911))/COUNTIFS(Tbl案件[發生管轄],"本轄",Tbl案件[歸屬年度],(YEAR(今日)-1911),Tbl案件[計入發生數],"是"),0),"0.0%") | G8: =IF(IFERROR(COUNTIFS(Tbl案件[查獲管轄],"本轄",Tbl案件[是否破獲],"是",Tbl案件[歸屬年度],(YEAR(今日)-1911))/COUNTIFS(Tbl案件[發生管轄],"本轄",Tbl案件[歸屬年度],(YEAR(今日)-1911),Tbl案件[計入發生數],"是"),0)>=1,"✓ 達標","● 待達標")
A9: 分局破獲率： | C9: =REPT("█",MIN(20,ROUND(IFERROR(COUNTIFS(Tbl案件[發生管轄],"本轄",Tbl案件[是否破獲],"是",Tbl案件[歸屬年度],(YEAR(今日)-1911))/COUNTIFS(Tbl案件[發生管轄],"本轄",Tbl案件[歸屬年度],(YEAR(今日)-1911),Tbl案件[計入發生數],"是"),0)*20,0)))&" "&TEXT(IFERROR(COUNTIFS(Tbl案件[發生管轄],"本轄",Tbl案件[是否破獲],"是",Tbl案件[歸屬年度],(YEAR(今日)-1911))/COUNTIFS(Tbl案件[發生管轄],"本轄",Tbl案件[歸屬年度],(YEAR(今日)-1911),Tbl案件[計入發生數],"是"),0),"0.0%") | G9: 100% 基準
A10: ="差異分析：本所 vs 分局 差 "&IFERROR(COUNTIFS(Tbl案件[查獲管轄],"本轄",Tbl案件[是否破獲],"是",Tbl案件[歸屬年度],(YEAR(今日)-1911))-COUNTIFS(Tbl案件[發生管轄],"本轄",Tbl案件[是否破獲],"是",Tbl案件[歸屬年度],(YEAR(今日)-1911)),0)&" 件 = 拘提掃碼車手破他轄 "&IFERROR(COUNTIFS(Tbl案件[發生管轄],"他轄",Tbl案件[查獲管轄],"本轄",Tbl案件[歸屬年度],(YEAR(今日)-1911)),0)&" 件 + 本轄已破未移送 "&IFERROR(COUNTIFS(Tbl案件[發生管轄],"本轄",Tbl案件[案件狀況],"已破獲未移送",Tbl案件[歸屬年度],(YEAR(今日)-1911)),0)&" 件"
A12: 貳 重點案類（竊盜 / 詐欺）
A13: ="🔵 竊盜：發生 "&IFERROR(COUNTIFS(Tbl案件[案類分類],"竊盜",Tbl案件[發生管轄],"本轄",Tbl案件[歸屬年度],(YEAR(今日)-1911),Tbl案件[計入發生數],"是"),0)&" / 破獲 "&IFERROR(COUNTIFS(Tbl案件[案類分類],"竊盜",Tbl案件[查獲管轄],"本轄",Tbl案件[是否破獲],"是",Tbl案件[歸屬年度],(YEAR(今日)-1911)),0)&" / 破獲率 "&TEXT(IFERROR(COUNTIFS(Tbl案件[案類分類],"竊盜",Tbl案件[查獲管轄],"本轄",Tbl案件[是否破獲],"是",Tbl案件[歸屬年度],(YEAR(今日)-1911))/COUNTIFS(Tbl案件[案類分類],"竊盜",Tbl案件[發生管轄],"本轄",Tbl案件[歸屬年度],(YEAR(今日)-1911),Tbl案件[計入發生數],"是"),0),"0.0%") | E13: ="🟢 詐欺：發生 "&IFERROR(COUNTIFS(Tbl案件[案類分類],"詐欺",Tbl案件[發生管轄],"本轄",Tbl案件[歸屬年度],(YEAR(今日)-1911),Tbl案件[計入發生數],"是"),0)&" / 破獲 "&IFERROR(COUNTIFS(Tbl案件[案類分類],"詐欺",Tbl案件[查獲管轄],"本轄",Tbl案件[是否破獲],"是",Tbl案件[歸屬年度],(YEAR(今日)-1911)),0)&" / 破獲率 "&TEXT(IFERROR(COUNTIFS(Tbl案件[案類分類],"詐欺",Tbl案件[查獲管轄],"本轄",Tbl案件[是否破獲],"是",Tbl案件[歸屬年度],(YEAR(今日)-1911))/COUNTIFS(Tbl案件[案類分類],"詐欺",Tbl案件[發生管轄],"本轄",Tbl案件[歸屬年度],(YEAR(今日)-1911),Tbl案件[計入發生數],"是"),0),"0.0%")
A24: 參 未破案件與其他管制
A25: 分類原因（手動填） | D25: 件數（手動） | E25: 補充說明（手動填）
A26: 他轄發生暫掛 | D26: 0
A27: 網路詐欺跨境 | D27: 0
A28: 無監視器卷宗 | D28: 0
A29: ─ 總計（手動 vs 自動）─ | D29: =SUM(D26:D28) | E29: =" 自動算未破："&IFERROR(COUNTIFS(Tbl案件[發生管轄],"本轄",Tbl案件[案件狀況],"尚未偵破",Tbl案件[歸屬年度],(YEAR(今日)-1911),Tbl案件[計入發生數],"是"),0)&" 件 ｜ 若不一致請補分類"
A30: ="🛡 婦幼案件："&IF(婦幼件數=0,"目前尚無管制案件",婦幼件數&" 件 列管中") | E30: ="🔍 協尋人口："&IF(協尋件數=0,"目前尚無管制案件",協尋件數&" 件 列管中")
A32: ="報告人："&派出所名稱&"所長 ｜ 破獲率基準：100% ｜ 本所統計：查獲管轄=本轄；分局統計：發生管轄=本轄 ｜ 製表："&TEXT(今日,"e/mm/dd")
Q99: [helper] 竊盜環形圖 | S99: [helper] 詐欺環形圖
Q100: 已破 | R100: =IFERROR(COUNTIFS(Tbl案件[案類分類],"竊盜",Tbl案件[查獲管轄],"本轄",Tbl案件[是否破獲],"是",Tbl案件[歸屬年度],(YEAR(今日)-1911)),0) | S100: 已破 | T100: =IFERROR(COUNTIFS(Tbl案件[案類分類],"詐欺",Tbl案件[查獲管轄],"本轄",Tbl案件[是否破獲],"是",Tbl案件[歸屬年度],(YEAR(今日)-1911)),0)
Q101: 尚未偵破 | R101: =MAX(0,IFERROR(COUNTIFS(Tbl案件[案類分類],"竊盜",Tbl案件[發生管轄],"本轄",Tbl案件[歸屬年度],(YEAR(今日)-1911),Tbl案件[計入發生數],"是")-COUNTIFS(Tbl案件[案類分類],"竊盜",Tbl案件[查獲管轄],"本轄",Tbl案件[是否破獲],"是",Tbl案件[歸屬年度],(YEAR(今日)-1911)),0)) | S101: 尚未偵破 | T101: =MAX(0,IFERROR(COUNTIFS(Tbl案件[案類分類],"詐欺",Tbl案件[發生管轄],"本轄",Tbl案件[歸屬年度],(YEAR(今日)-1911),Tbl案件[計入發生數],"是")-COUNTIFS(Tbl案件[案類分類],"詐欺",Tbl案件[查獲管轄],"本轄",Tbl案件[是否破獲],"是",Tbl案件[歸屬年度],(YEAR(今日)-1911)),0))

Sheet 長官5分鐘報告
A1: =" 📜 " & 派出所名稱 & " ｜ 中華民國 " & (YEAR(今日)-1911) & " 年 " & TEXT(MONTH(今日),"00") & " 月勤務狀況報告"
A2: =" " & 警察局名稱 & " · " & 分局名稱 & " · " & 派出所名稱 & " ｜ 製表 " & TEXT(今日,"e/mm/dd") & " ｜ Pyramid Principle 5 分鐘簡報"
A3: =" 📌 報告人：" & 派出所名稱 & "所長 ｜ 呈：分局督導官 ｜ 本報告由系統自動聚合 + 所長行動方案"
A5: ★ 結論（一句話總結，公式自動）
A6: =IF(管制總覽!A25>0,"🚨 本月狀態嚴峻：9 大 KPI 有 " & 管制總覽!A25 & " 項紅燈，需立即處置（建議優先處理未破刑案與毒調候選）",IF(管制總覽!G25>0,"⚠ 本月狀態尚可：" & 管制總覽!G25 & " 項黃燈需關注，建議排入週會檢討；其餘 KPI 達標","✓ 本月狀態良好：9 大 KPI 全綠燈通過，建議持續維持"))
A9: ★ 三大重點（按優先順序：刑案 → 毒調 → 交通）
A10: 🔍 刑案績效
A11: =" ① 本所統計破獲率：" & TEXT(IFERROR(COUNTIFS(Tbl案件[查獲管轄],"本轄",Tbl案件[是否破獲],"是",Tbl案件[歸屬年度],(YEAR(今日)-1911))/COUNTIFS(Tbl案件[發生管轄],"本轄",Tbl案件[歸屬年度],(YEAR(今日)-1911),Tbl案件[計入發生數],"是"),0),"0.0%") & "（年度累計）"
A12: =" ② 案件狀況分布：尚未偵破 " & IFERROR(COUNTIFS(Tbl案件[案件狀況],"尚未偵破",Tbl案件[發生管轄],"本轄",Tbl案件[歸屬年度],(YEAR(今日)-1911)),0) & " 件 已破獲未移送 " & IFERROR(COUNTIFS(Tbl案件[案件狀況],"已破獲未移送",Tbl案件[歸屬年度],(YEAR(今日)-1911)),0) & " 件 已移送 " & IFERROR(COUNTIFS(Tbl案件[案件狀況],"已移送",Tbl案件[歸屬年度],(YEAR(今日)-1911)),0) & " 件"
A13: =" ③ 重點案類：竊盜破獲率 " & TEXT(管制總覽!G9,"0.0%") & " 詐欺破獲率 " & TEXT(管制總覽!M9,"0.0%")
A14: 💊 毒品調驗
A15: =" ① 毒調率：" & TEXT(IFERROR(SUM(Tbl毒調[是否到驗])/COUNTA(Tbl毒調[姓名]),0),"0.0%") & "（目標 " & TEXT(毒調率目標,"0%") & "）"
A16: =" ② 列管 " & COUNTA(Tbl毒調[姓名]) & " 人 完成到驗（含通緝/強採/在監）" & SUM(Tbl毒調[是否到驗]) & " 人"
A17: =" ③ 應強採候選：" & SUM(Tbl毒調[候選旗標]) & " 人未到驗待處理"
A18: 🚦 交通取締
A19: =" ① 總達成率：" & TEXT(IFERROR(交通績效管制!E8,0),"0.0%")
A20: =" ② 達標項數：" & COUNTIF(交通績效管制!D14:D19,">="&0.8) & " ／ 6 項違規"
A21: =" ③ 主要違規：酒駕 " & IFERROR(COUNTIF(Tbl交通[違規項目],"*酒駕*"),0) & " 件 闖紅燈 " & IFERROR(COUNTIF(Tbl交通[違規項目],"*闖紅燈*"),0) & " 件"
A23: ★ 下月行動方案（手動輸入區 — 所長判斷裁示，公式不代生）
A24: 行動 1：（請所長手填，例：本月加強 XX 路段巡邏，目標降低詐欺 X 件）
A25: 行動 2：（請所長手填）
A26: 行動 3：（請所長手填）
A27: 備註：（必要時補充說明）
A29: 🏆 本月 Top 3 員警（公式自動，來源頁 10 績效統計）
A30: 排名 | B30: 員警姓名 | C30: 全般破獲 | D30: 竊盜 | E30: 詐欺 | F30: 毒品 | G30: 暴力犯罪 | H30: 其他
A31: =IFERROR(績效統計!A19,"") | B31: =IFERROR(績效統計!B19,"") | C31: =IFERROR(績效統計!C19,"") | D31: =IFERROR(績效統計!D19,"") | E31: =IFERROR(績效統計!E19,"") | F31: =IFERROR(績效統計!F19,"") | G31: =IFERROR(績效統計!G19,"") | H31: =IFERROR(績效統計!H19,"")
A32: =IFERROR(績效統計!A20,"") | B32: =IFERROR(績效統計!B20,"") | C32: =IFERROR(績效統計!C20,"") | D32: =IFERROR(績效統計!D20,"") | E32: =IFERROR(績效統計!E20,"") | F32: =IFERROR(績效統計!F20,"") | G32: =IFERROR(績效統計!G20,"") | H32: =IFERROR(績效統計!H20,"")
A33: =IFERROR(績效統計!A21,"") | B33: =IFERROR(績效統計!B21,"") | C33: =IFERROR(績效統計!C21,"") | D33: =IFERROR(績效統計!D21,"") | E33: =IFERROR(績效統計!E21,"") | F33: =IFERROR(績效統計!F21,"") | G33: =IFERROR(績效統計!G21,"") | H33: =IFERROR(績效統計!H21,"")
A35: 所長：__________________ 簽章 | E35: 督導官：__________________ 簽章
A36: ="© KKEVIN-LIN-2026-V2.0 ｜ Pyramid Principle 5 分鐘簡報 ｜ A4 直式可獨立交付督導官 ｜ 製表："&TEXT(今日,"e/mm/dd")

Sheet 對上級機關上呈
A1: 📋 對上級機關上呈（公文格式 — 三層動態切換）
A2: =" " & 警察局名稱 & " · " & 分局名稱 & " · " & 派出所名稱 & " ｜ 中華民國 " & (YEAR(今日)-1911) & " 年 " & TEXT(MONTH(今日),"00") & " 月 ｜ 公文體例：三線表 / 官方藍 / 章戳"
A3: 上呈對象： | B3: 對分局 | C3: =CHOOSE(MATCH(B3,{"對分局","對警察局","對警政署"},0),"📂 詳細五領域 KPI ｜ 列印 A4 ×2-3 頁","📂 月報摘要 + 全市比較 ｜ 列印 A4 ×1-2 頁","📂 全國標準格式 ｜ 列印 A4 ×1 頁")
A5: ★ 公文抬頭（依上呈對象動態切換）
A6: =CHOOSE(MATCH(B3,{"對分局","對警察局","對警政署"},0),派出所名稱 & " 中華民國 " & (YEAR(今日)-1911) & " 年 " & TEXT(MONTH(今日),"00") & " 月勤務報告（呈分局）",派出所名稱 & " 中華民國 " & (YEAR(今日)-1911) & " 年 " & TEXT(MONTH(今日),"00") & " 月績效月報（呈警察局）",派出所名稱 & " 中華民國 " & (YEAR(今日)-1911) & " 年 " & TEXT(MONTH(今日),"00") & " 月標準統計（呈警政署）")
A7: 受文者： | C7: =CHOOSE(MATCH(B3,{"對分局","對警察局","對警政署"},0),分局名稱 & " 督導官",警察局名稱 & " 刑事警察大隊","內政部警政署刑事警察局")
A8: 主旨： | C8: =CHOOSE(MATCH(B3,{"對分局","對警察局","對警政署"},0),"呈報本所本月勤務狀況、案件管制、毒調人口、交通取締五大領域 KPI","呈報本所本月績效摘要，並與全市平均比較","呈報本所本月全國統一格式刑案統計")
A10: ★ 主要 KPI（年度累計，SSOT 自動聚合）
A11: 編號 | B11: KPI 項目 | C11: 數值 | E11: 目標 | G11: 達標狀態
A12: 01 | B12: 全般破獲率 | C12: =IFERROR(COUNTIFS(Tbl案件[查獲管轄],"本轄",Tbl案件[是否破獲],"是",Tbl案件[歸屬年度],(YEAR(今日)-1911))/COUNTIFS(Tbl案件[發生管轄],"本轄",Tbl案件[歸屬年度],(YEAR(今日)-1911),Tbl案件[計入發生數],"是"),0) | E12: =0.85 | G12: =IF(IFERROR(C12>=0.85,FALSE),"● 達標","● 未達標")
A13: 02 | B13: 竊盜破獲率 | C13: =管制總覽!G9 | E13: =0.80 | G13: =IF(IFERROR(C13>=0.80,FALSE),"● 達標","● 未達標")
A14: 03 | B14: 詐欺破獲率 | C14: =管制總覽!M9 | E14: =0.60 | G14: =IF(IFERROR(C14>=0.60,FALSE),"● 達標","● 未達標")
A15: 04 | B15: 毒調率 | C15: =管制總覽!A14 | E15: =毒調率目標 | G15: =IF(IFERROR(C15>=毒調率目標,FALSE),"● 達標","● 未達標")
A16: 05 | B16: 未到驗人口 | C16: =管制總覽!G14 | E16: =5 | G16: =IF(IFERROR(C16<=5,FALSE),"● 達標","● 未達標")
A17: 06 | B17: 未破案件 | C17: =管制總覽!M14 | E17: =5 | G17: =IF(IFERROR(C17<=5,FALSE),"● 達標","● 未達標")
A18: 07 | B18: 交通達成率 | C18: =交通績效管制!E8 | E18: =0.80 | G18: =IF(IFERROR(C18>=0.80,FALSE),"● 達標","● 未達標")
A19: 08 | B19: 本所員警在職數 | C19: =COUNTIF(設定表!$D$13:$D$72,"是") | E19: — | G19: ="—"
A21: ★ 必附附件（依上呈對象動態切換）
A22: =CHOOSE(MATCH(B3,{"對分局","對警察局","對警政署"},0)," 附件 1：未破案件明細表（頁 6 列印）"," 附件 1：案類分類統計（頁 10 列印）"," 附件 1：標準破獲率表（頁 2 列印）")
A23: =CHOOSE(MATCH(B3,{"對分局","對警察局","對警政署"},0)," 附件 2：員警勤務統計（頁 10 列印）"," 附件 2：達標未達標項目清單（頁 9 列印）"," 附件 2：列管人口處理（頁 8 列印）")
A24: =CHOOSE(MATCH(B3,{"對分局","對警察局","對警政署"},0)," 附件 3：毒品調驗人口明細（頁 8 列印）"," 附件 3：與全市平均比較表"," 附件 3：違規取締達成統計（頁 9 列印）")
A25: =CHOOSE(MATCH(B3,{"對分局","對警察局","對警政署"},0)," 附件 4：跨期間趨勢分析（頁 12 列印）"," （無）"," （無）")
A27: 發文人：所長 __________________ 簽章 | E27: 收文機關承辦：__________________ 簽章
A28: ="© KKEVIN-LIN-2026-V2.0 ｜ CHOOSE/INDIRECT 動態切換 ｜ 上呈對象：" & B3 & " ｜ 製表："&TEXT(今日,"e/mm/dd")

Sheet 案件資料庫
A1: 📋 案件資料庫
A2: ="📊 容量：" & IFERROR(COUNTA(Tbl案件[編號]),0) & " / 1000 列 ｜ " & IF(COUNTA(Tbl案件[編號])>=950,"🚨 容量即將滿，請立即歸檔",IF(COUNTA(Tbl案件[編號])>=800,"⚠ 已達 80% 容量警戒，建議規劃歸檔","✓ 容量充裕")) & " ｜ 🔒 受保護（密碼：KD2026）"
A4: 💡 新增資料：① 點下方任一空白列 → ② 直接 key 入。 Excel Table 自動擴展。淡黃色 = 可輸入欄位，淡灰色 = 公式自動算（請勿改）
A5: 🔗 SSOT：本表 Tbl案件 是其他頁面公式的資料源。修改後其他頁的 KPI、報告、檢核都會即時更新
A14: 編號 | B14: 案類 | C14: E化案號 | D14: 發生時間 | E14: 發生地點 | F14: 破獲時間 | G14: 破獲地點 | H14: 案情摘要 | I14: 偵辦進度 | J14: 案件狀況 | K14: 發生管轄 | L14: 查獲管轄 | M14: 承辦人 | N14: 備註 | O14: 涉案金額 | P14: 建立日期 | Q14: 建立者 | R14: 是否破獲 | S14: 歸屬年度 | T14: 案類分類 | U14: 是否納入統計 | V14: 主排序鍵 | W14: 績效類別 | X14: 計入發生數 | Y14: 自填案類
R15: =IFERROR(IF(OR([@案件狀況]="已破獲未移送",[@案件狀況]="已移送"),"是","否"),"") | S15: =IFERROR(IF([@發生時間]="","",YEAR([@發生時間])-1911),"") | T15: =IFERROR(INDEX(案類分類清單,MATCH([@案類],案類名稱清單,0)),"") | U15: =IFERROR(INDEX(納入全般清單,MATCH([@案類],案類名稱清單,0)),"否") | V15: =IFERROR([@歸屬年度]*10000+IFERROR(MATCH([@案件狀況],{"尚未偵破","已破獲未移送","已移送","簽結"},0),0)*100+ROW(),0) | X15: =IFERROR(IF([@績效類別]="","是","否"),"是")
R16: =IFERROR(IF(OR([@案件狀況]="已破獲未移送",[@案件狀況]="已移送"),"是","否"),"") | S16: =IFERROR(IF([@發生時間]="","",YEAR([@發生時間])-1911),"") | T16: =IFERROR(INDEX(案類分類清單,MATCH([@案類],案類名稱清單,0)),"") | U16: =IFERROR(INDEX(納入全般清單,MATCH([@案類],案類名稱清單,0)),"否") | V16: =IFERROR([@歸屬年度]*10000+IFERROR(MATCH([@案件狀況],{"尚未偵破","已破獲未移送","已移送","簽結"},0),0)*100+ROW(),0) | X16: =IFERROR(IF([@績效類別]="","是","否"),"是")
R17: =IFERROR(IF(OR([@案件狀況]="已破獲未移送",[@案件狀況]="已移送"),"是","否"),"") | S17: =IFERROR(IF([@發生時間]="","",YEAR([@發生時間])-1911),"") | T17: =IFERROR(INDEX(案類分類清單,MATCH([@案類],案類名稱清單,0)),"") | U17: =IFERROR(INDEX(納入全般清單,MATCH([@案類],案類名稱清單,0)),"否") | V17: =IFERROR([@歸屬年度]*10000+IFERROR(MATCH([@案件狀況],{"尚未偵破","已破獲未移送","已移送","簽結"},0),0)*100+ROW(),0) | X17: =IFERROR(IF([@績效類別]="","是","否"),"是")
R18: =IFERROR(IF(OR([@案件狀況]="已破獲未移送",[@案件狀況]="已移送"),"是","否"),"") | S18: =IFERROR(IF([@發生時間]="","",YEAR([@發生時間])-1911),"") | T18: =IFERROR(INDEX(案類分類清單,MATCH([@案類],案類名稱清單,0)),"") | U18: =IFERROR(INDEX(納入全般清單,MATCH([@案類],案類名稱清單,0)),"否") | V18: =IFERROR([@歸屬年度]*10000+IFERROR(MATCH([@案件狀況],{"尚未偵破","已破獲未移送","已移送","簽結"},0),0)*100+ROW(),0) | X18: =IFERROR(IF([@績效類別]="","是","否"),"是")
R19: =IFERROR(IF(OR([@案件狀況]="已破獲未移送",[@案件狀況]="已移送"),"是","否"),"") | S19: =IFERROR(IF([@發生時間]="","",YEAR([@發生時間])-1911),"") | T19: =IFERROR(INDEX(案類分類清單,MATCH([@案類],案類名稱清單,0)),"") | U19: =IFERROR(INDEX(納入全般清單,MATCH([@案類],案類名稱清單,0)),"否") | V19: =IFERROR([@歸屬年度]*10000+IFERROR(MATCH([@案件狀況],{"尚未偵破","已破獲未移送","已移送","簽結"},0),0)*100+ROW(),0) | X19: =IFERROR(IF([@績效類別]="","是","否"),"是")
R20: =IFERROR(IF(OR([@案件狀況]="已破獲未移送",[@案件狀況]="已移送"),"是","否"),"") | S20: =IFERROR(IF([@發生時間]="","",YEAR([@發生時間])-1911),"") | T20: =IFERROR(INDEX(案類分類清單,MATCH([@案類],案類名稱清單,0)),"") | U20: =IFERROR(INDEX(納入全般清單,MATCH([@案類],案類名稱清單,0)),"否") | V20: =IFERROR([@歸屬年度]*10000+IFERROR(MATCH([@案件狀況],{"尚未偵破","已破獲未移送","已移送","簽結"},0),0)*100+ROW(),0) | X20: =IFERROR(IF([@績效類別]="","是","否"),"是")
R21: =IFERROR(IF(OR([@案件狀況]="已破獲未移送",[@案件狀況]="已移送"),"是","否"),"") | S21: =IFERROR(IF([@發生時間]="","",YEAR([@發生時間])-1911),"") | T21: =IFERROR(INDEX(案類分類清單,MATCH([@案類],案類名稱清單,0)),"") | U21: =IFERROR(INDEX(納入全般清單,MATCH([@案類],案類名稱清單,0)),"否") | V21: =IFERROR([@歸屬年度]*10000+IFERROR(MATCH([@案件狀況],{"尚未偵破","已破獲未移送","已移送","簽結"},0),0)*100+ROW(),0) | X21: =IFERROR(IF([@績效類別]="","是","否"),"是")
R22: =IFERROR(IF(OR([@案件狀況]="已破獲未移送",[@案件狀況]="已移送"),"是","否"),"") | S22: =IFERROR(IF([@發生時間]="","",YEAR([@發生時間])-1911),"") | T22: =IFERROR(INDEX(案類分類清單,MATCH([@案類],案類名稱清單,0)),"") | U22: =IFERROR(INDEX(納入全般清單,MATCH([@案類],案類名稱清單,0)),"否") | V22: =IFERROR([@歸屬年度]*10000+IFERROR(MATCH([@案件狀況],{"尚未偵破","已破獲未移送","已移送","簽結"},0),0)*100+ROW(),0) | X22: =IFERROR(IF([@績效類別]="","是","否"),"是")
R23: =IFERROR(IF(OR([@案件狀況]="已破獲未移送",[@案件狀況]="已移送"),"是","否"),"") | S23: =IFERROR(IF([@發生時間]="","",YEAR([@發生時間])-1911),"") | T23: =IFERROR(INDEX(案類分類清單,MATCH([@案類],案類名稱清單,0)),"") | U23: =IFERROR(INDEX(納入全般清單,MATCH([@案類],案類名稱清單,0)),"否") | V23: =IFERROR([@歸屬年度]*10000+IFERROR(MATCH([@案件狀況],{"尚未偵破","已破獲未移送","已移送","簽結"},0),0)*100+ROW(),0) | X23: =IFERROR(IF([@績效類別]="","是","否"),"是")
R24: =IFERROR(IF(OR([@案件狀況]="已破獲未移送",[@案件狀況]="已移送"),"是","否"),"") | S24: =IFERROR(IF([@發生時間]="","",YEAR([@發生時間])-1911),"") | T24: =IFERROR(INDEX(案類分類清單,MATCH([@案類],案類名稱清單,0)),"") | U24: =IFERROR(INDEX(納入全般清單,MATCH([@案類],案類名稱清單,0)),"否") | V24: =IFERROR([@歸屬年度]*10000+IFERROR(MATCH([@案件狀況],{"尚未偵破","已破獲未移送","已移送","簽結"},0),0)*100+ROW(),0) | X24: =IFERROR(IF([@績效類別]="","是","否"),"是")
R25: =IFERROR(IF(OR([@案件狀況]="已破獲未移送",[@案件狀況]="已移送"),"是","否"),"") | S25: =IFERROR(IF([@發生時間]="","",YEAR([@發生時間])-1911),"") | T25: =IFERROR(INDEX(案類分類清單,MATCH([@案類],案類名稱清單,0)),"") | U25: =IFERROR(INDEX(納入全般清單,MATCH([@案類],案類名稱清單,0)),"否") | V25: =IFERROR([@歸屬年度]*10000+IFERROR(MATCH([@案件狀況],{"尚未偵破","已破獲未移送","已移送","簽結"},0),0)*100+ROW(),0) | X25: =IFERROR(IF([@績效類別]="","是","否"),"是")
R26: =IFERROR(IF(OR([@案件狀況]="已破獲未移送",[@案件狀況]="已移送"),"是","否"),"") | S26: =IFERROR(IF([@發生時間]="","",YEAR([@發生時間])-1911),"") | T26: =IFERROR(INDEX(案類分類清單,MATCH([@案類],案類名稱清單,0)),"") | U26: =IFERROR(INDEX(納入全般清單,MATCH([@案類],案類名稱清單,0)),"否") | V26: =IFERROR([@歸屬年度]*10000+IFERROR(MATCH([@案件狀況],{"尚未偵破","已破獲未移送","已移送","簽結"},0),0)*100+ROW(),0) | X26: =IFERROR(IF([@績效類別]="","是","否"),"是")
... R218: =IFERROR(IF(OR([@案件狀況]="已破獲未移送",[@案件狀況]="已移送"),"是","否"),"") | S218: =IFERROR(IF([@發生時間]="","",YEAR([@發生時間])-1911),"") | T218: =IFERROR(INDEX(案類分類清單,MATCH([@案類],案類名稱清單,0)),"") | U218: =IFERROR(INDEX(納入全般清單,MATCH([@案類],案類名稱清單,0)),"否") | V218: =IFERROR([@歸屬年度]*10000+IFERROR(MATCH([@案件狀況],{"尚未偵破","已破獲未移送","已移送","簽結"},0),0)*100+ROW(),0) | X218: =IFERROR(IF([@績效類別]="","是","否"),"是")

Sheet 刑案管制
A1: 🔍 刑案管制（兩區段並呈：尚未偵破 + 已破獲未移送）
A2: =" "&警察局名稱&" · "&分局名稱&" · "&派出所名稱&" ｜ 中華民國 "&(YEAR(今日)-1911)&" 年累計（截至 "&TEXT(今日,"mm/dd")&"）｜ 資料源：Tbl案件 (SSOT)"
A4: ="📌 派出所主管兩階段：尚未偵破（要破）+ 已破獲未移送（催偵查隊）｜ 已移送屬地檢端不在此清單細列"
A5: ● 尚未偵破 | C5: ➜ | D5: ● 已破獲未移送 | F5: ➜ | G5: ● 已移送（地檢）
A7: ="🔴 尚未偵破："&IFERROR(COUNTIFS(Tbl案件[案件狀況],"尚未偵破",Tbl案件[發生管轄],"本轄",Tbl案件[歸屬年度],(YEAR(今日)-1911)),0)&" 件" | D7: ="🟡 已破獲未移送："&IFERROR(COUNTIFS(Tbl案件[案件狀況],"已破獲未移送",Tbl案件[查獲管轄],"本轄",Tbl案件[歸屬年度],(YEAR(今日)-1911)),0)&" 件" | G7: ="✓ 已移送（地檢）："&IFERROR(COUNTIFS(Tbl案件[案件狀況],"已移送",Tbl案件[查獲管轄],"本轄",Tbl案件[歸屬年度],(YEAR(今日)-1911)),0)&" 件"
A9: =" 🔴 尚未偵破清單（"&IFERROR(COUNTIFS(Tbl案件[案件狀況],"尚未偵破",Tbl案件[發生管轄],"本轄",Tbl案件[歸屬年度],(YEAR(今日)-1911)),0)&" 件，最多顯示前 15 件）"
A10: 編號 | B10: 案類 | C10: 發生時間 | D10: 發生地 | E10: 破獲時間 | F10: 案件狀況 | G10: 偵辦進度 | H10: 承辦人 | I10: 備註
A11: =IFERROR(INDEX(Tbl案件[編號],MATCH(1,$S$100:$S$299,0)),"") | B11: =IFERROR(INDEX(Tbl案件[案類],MATCH(1,$S$100:$S$299,0)),"") | C11: =IFERROR(INDEX(Tbl案件[發生時間],MATCH(1,$S$100:$S$299,0)),"") | D11: =IFERROR(INDEX(Tbl案件[發生地點],MATCH(1,$S$100:$S$299,0)),"") | E11: =IFERROR(INDEX(Tbl案件[破獲時間],MATCH(1,$S$100:$S$299,0)),"") | F11: =IFERROR(INDEX(Tbl案件[案件狀況],MATCH(1,$S$100:$S$299,0)),"") | G11: =IFERROR(INDEX(Tbl案件[偵辦進度],MATCH(1,$S$100:$S$299,0)),"") | H11: =IFERROR(INDEX(Tbl案件[承辦人],MATCH(1,$S$100:$S$299,0)),"") | I11: =IFERROR(INDEX(Tbl案件[備註],MATCH(1,$S$100:$S$299,0)),"")
A12: =IFERROR(INDEX(Tbl案件[編號],MATCH(2,$S$100:$S$299,0)),"") | B12: =IFERROR(INDEX(Tbl案件[案類],MATCH(2,$S$100:$S$299,0)),"") | C12: =IFERROR(INDEX(Tbl案件[發生時間],MATCH(2,$S$100:$S$299,0)),"") | D12: =IFERROR(INDEX(Tbl案件[發生地點],MATCH(2,$S$100:$S$299,0)),"") | E12: =IFERROR(INDEX(Tbl案件[破獲時間],MATCH(2,$S$100:$S$299,0)),"") | F12: =IFERROR(INDEX(Tbl案件[案件狀況],MATCH(2,$S$100:$S$299,0)),"") | G12: =IFERROR(INDEX(Tbl案件[偵辦進度],MATCH(2,$S$100:$S$299,0)),"") | H12: =IFERROR(INDEX(Tbl案件[承辦人],MATCH(2,$S$100:$S$299,0)),"") | I12: =IFERROR(INDEX(Tbl案件[備註],MATCH(2,$S$100:$S$299,0)),"")
A13: =IFERROR(INDEX(Tbl案件[編號],MATCH(3,$S$100:$S$299,0)),"") | B13: =IFERROR(INDEX(Tbl案件[案類],MATCH(3,$S$100:$S$299,0)),"") | C13: =IFERROR(INDEX(Tbl案件[發生時間],MATCH(3,$S$100:$S$299,0)),"") | D13: =IFERROR(INDEX(Tbl案件[發生地點],MATCH(3,$S$100:$S$299,0)),"") | E13: =IFERROR(INDEX(Tbl案件[破獲時間],MATCH(3,$S$100:$S$299,0)),"") | F13: =IFERROR(INDEX(Tbl案件[案件狀況],MATCH(3,$S$100:$S$299,0)),"") | G13: =IFERROR(INDEX(Tbl案件[偵辦進度],MATCH(3,$S$100:$S$299,0)),"") | H13: =IFERROR(INDEX(Tbl案件[承辦人],MATCH(3,$S$100:$S$299,0)),"") | I13: =IFERROR(INDEX(Tbl案件[備註],MATCH(3,$S$100:$S$299,0)),"")
A14: =IFERROR(INDEX(Tbl案件[編號],MATCH(4,$S$100:$S$299,0)),"") | B14: =IFERROR(INDEX(Tbl案件[案類],MATCH(4,$S$100:$S$299,0)),"") | C14: =IFERROR(INDEX(Tbl案件[發生時間],MATCH(4,$S$100:$S$299,0)),"") | D14: =IFERROR(INDEX(Tbl案件[發生地點],MATCH(4,$S$100:$S$299,0)),"") | E14: =IFERROR(INDEX(Tbl案件[破獲時間],MATCH(4,$S$100:$S$299,0)),"") | F14: =IFERROR(INDEX(Tbl案件[案件狀況],MATCH(4,$S$100:$S$299,0)),"") | G14: =IFERROR(INDEX(Tbl案件[偵辦進度],MATCH(4,$S$100:$S$299,0)),"") | H14: =IFERROR(INDEX(Tbl案件[承辦人],MATCH(4,$S$100:$S$299,0)),"") | I14: =IFERROR(INDEX(Tbl案件[備註],MATCH(4,$S$100:$S$299,0)),"")
A15: =IFERROR(INDEX(Tbl案件[編號],MATCH(5,$S$100:$S$299,0)),"") | B15: =IFERROR(INDEX(Tbl案件[案類],MATCH(5,$S$100:$S$299,0)),"") | C15: =IFERROR(INDEX(Tbl案件[發生時間],MATCH(5,$S$100:$S$299,0)),"") | D15: =IFERROR(INDEX(Tbl案件[發生地點],MATCH(5,$S$100:$S$299,0)),"") | E15: =IFERROR(INDEX(Tbl案件[破獲時間],MATCH(5,$S$100:$S$299,0)),"") | F15: =IFERROR(INDEX(Tbl案件[案件狀況],MATCH(5,$S$100:$S$299,0)),"") | G15: =IFERROR(INDEX(Tbl案件[偵辦進度],MATCH(5,$S$100:$S$299,0)),"") | H15: =IFERROR(INDEX(Tbl案件[承辦人],MATCH(5,$S$100:$S$299,0)),"") | I15: =IFERROR(INDEX(Tbl案件[備註],MATCH(5,$S$100:$S$299,0)),"")
A16: =IFERROR(INDEX(Tbl案件[編號],MATCH(6,$S$100:$S$299,0)),"") | B16: =IFERROR(INDEX(Tbl案件[案類],MATCH(6,$S$100:$S$299,0)),"") | C16: =IFERROR(INDEX(Tbl案件[發生時間],MATCH(6,$S$100:$S$299,0)),"") | D16: =IFERROR(INDEX(Tbl案件[發生地點],MATCH(6,$S$100:$S$299,0)),"") | E16: =IFERROR(INDEX(Tbl案件[破獲時間],MATCH(6,$S$100:$S$299,0)),"") | F16: =IFERROR(INDEX(Tbl案件[案件狀況],MATCH(6,$S$100:$S$299,0)),"") | G16: =IFERROR(INDEX(Tbl案件[偵辦進度],MATCH(6,$S$100:$S$299,0)),"") | H16: =IFERROR(INDEX(Tbl案件[承辦人],MATCH(6,$S$100:$S$299,0)),"") | I16: =IFERROR(INDEX(Tbl案件[備註],MATCH(6,$S$100:$S$299,0)),"")
A17: =IFERROR(INDEX(Tbl案件[編號],MATCH(7,$S$100:$S$299,0)),"") | B17: =IFERROR(INDEX(Tbl案件[案類],MATCH(7,$S$100:$S$299,0)),"") | C17: =IFERROR(INDEX(Tbl案件[發生時間],MATCH(7,$S$100:$S$299,0)),"") | D17: =IFERROR(INDEX(Tbl案件[發生地點],MATCH(7,$S$100:$S$299,0)),"") | E17: =IFERROR(INDEX(Tbl案件[破獲時間],MATCH(7,$S$100:$S$299,0)),"") | F17: =IFERROR(INDEX(Tbl案件[案件狀況],MATCH(7,$S$100:$S$299,0)),"") | G17: =IFERROR(INDEX(Tbl案件[偵辦進度],MATCH(7,$S$100:$S$299,0)),"") | H17: =IFERROR(INDEX(Tbl案件[承辦人],MATCH(7,$S$100:$S$299,0)),"") | I17: =IFERROR(INDEX(Tbl案件[備註],MATCH(7,$S$100:$S$299,0)),"")
A18: =IFERROR(INDEX(Tbl案件[編號],MATCH(8,$S$100:$S$299,0)),"") | B18: =IFERROR(INDEX(Tbl案件[案類],MATCH(8,$S$100:$S$299,0)),"") | C18: =IFERROR(INDEX(Tbl案件[發生時間],MATCH(8,$S$100:$S$299,0)),"") | D18: =IFERROR(INDEX(Tbl案件[發生地點],MATCH(8,$S$100:$S$299,0)),"") | E18: =IFERROR(INDEX(Tbl案件[破獲時間],MATCH(8,$S$100:$S$299,0)),"") | F18: =IFERROR(INDEX(Tbl案件[案件狀況],MATCH(8,$S$100:$S$299,0)),"") | G18: =IFERROR(INDEX(Tbl案件[偵辦進度],MATCH(8,$S$100:$S$299,0)),"") | H18: =IFERROR(INDEX(Tbl案件[承辦人],MATCH(8,$S$100:$S$299,0)),"") | I18: =IFERROR(INDEX(Tbl案件[備註],MATCH(8,$S$100:$S$299,0)),"")
A19: =IFERROR(INDEX(Tbl案件[編號],MATCH(9,$S$100:$S$299,0)),"") | B19: =IFERROR(INDEX(Tbl案件[案類],MATCH(9,$S$100:$S$299,0)),"") | C19: =IFERROR(INDEX(Tbl案件[發生時間],MATCH(9,$S$100:$S$299,0)),"") | D19: =IFERROR(INDEX(Tbl案件[發生地點],MATCH(9,$S$100:$S$299,0)),"") | E19: =IFERROR(INDEX(Tbl案件[破獲時間],MATCH(9,$S$100:$S$299,0)),"") | F19: =IFERROR(INDEX(Tbl案件[案件狀況],MATCH(9,$S$100:$S$299,0)),"") | G19: =IFERROR(INDEX(Tbl案件[偵辦進度],MATCH(9,$S$100:$S$299,0)),"") | H19: =IFERROR(INDEX(Tbl案件[承辦人],MATCH(9,$S$100:$S$299,0)),"") | I19: =IFERROR(INDEX(Tbl案件[備註],MATCH(9,$S$100:$S$299,0)),"")
A20: =IFERROR(INDEX(Tbl案件[編號],MATCH(10,$S$100:$S$299,0)),"") | B20: =IFERROR(INDEX(Tbl案件[案類],MATCH(10,$S$100:$S$299,0)),"") | C20: =IFERROR(INDEX(Tbl案件[發生時間],MATCH(10,$S$100:$S$299,0)),"") | D20: =IFERROR(INDEX(Tbl案件[發生地點],MATCH(10,$S$100:$S$299,0)),"") | E20: =IFERROR(INDEX(Tbl案件[破獲時間],MATCH(10,$S$100:$S$299,0)),"") | F20: =IFERROR(INDEX(Tbl案件[案件狀況],MATCH(10,$S$100:$S$299,0)),"") | G20: =IFERROR(INDEX(Tbl案件[偵辦進度],MATCH(10,$S$100:$S$299,0)),"") | H20: =IFERROR(INDEX(Tbl案件[承辦人],MATCH(10,$S$100:$S$299,0)),"") | I20: =IFERROR(INDEX(Tbl案件[備註],MATCH(10,$S$100:$S$299,0)),"")
A21: =IFERROR(INDEX(Tbl案件[編號],MATCH(11,$S$100:$S$299,0)),"") | B21: =IFERROR(INDEX(Tbl案件[案類],MATCH(11,$S$100:$S$299,0)),"") | C21: =IFERROR(INDEX(Tbl案件[發生時間],MATCH(11,$S$100:$S$299,0)),"") | D21: =IFERROR(INDEX(Tbl案件[發生地點],MATCH(11,$S$100:$S$299,0)),"") | E21: =IFERROR(INDEX(Tbl案件[破獲時間],MATCH(11,$S$100:$S$299,0)),"") | F21: =IFERROR(INDEX(Tbl案件[案件狀況],MATCH(11,$S$100:$S$299,0)),"") | G21: =IFERROR(INDEX(Tbl案件[偵辦進度],MATCH(11,$S$100:$S$299,0)),"") | H21: =IFERROR(INDEX(Tbl案件[承辦人],MATCH(11,$S$100:$S$299,0)),"") | I21: =IFERROR(INDEX(Tbl案件[備註],MATCH(11,$S$100:$S$299,0)),"")
A22: =IFERROR(INDEX(Tbl案件[編號],MATCH(12,$S$100:$S$299,0)),"") | B22: =IFERROR(INDEX(Tbl案件[案類],MATCH(12,$S$100:$S$299,0)),"") | C22: =IFERROR(INDEX(Tbl案件[發生時間],MATCH(12,$S$100:$S$299,0)),"") | D22: =IFERROR(INDEX(Tbl案件[發生地點],MATCH(12,$S$100:$S$299,0)),"") | E22: =IFERROR(INDEX(Tbl案件[破獲時間],MATCH(12,$S$100:$S$299,0)),"") | F22: =IFERROR(INDEX(Tbl案件[案件狀況],MATCH(12,$S$100:$S$299,0)),"") | G22: =IFERROR(INDEX(Tbl案件[偵辦進度],MATCH(12,$S$100:$S$299,0)),"") | H22: =IFERROR(INDEX(Tbl案件[承辦人],MATCH(12,$S$100:$S$299,0)),"") | I22: =IFERROR(INDEX(Tbl案件[備註],MATCH(12,$S$100:$S$299,0)),"")
A23: =IFERROR(INDEX(Tbl案件[編號],MATCH(13,$S$100:$S$299,0)),"") | B23: =IFERROR(INDEX(Tbl案件[案類],MATCH(13,$S$100:$S$299,0)),"") | C23: =IFERROR(INDEX(Tbl案件[發生時間],MATCH(13,$S$100:$S$299,0)),"") | D23: =IFERROR(INDEX(Tbl案件[發生地點],MATCH(13,$S$100:$S$299,0)),"") | E23: =IFERROR(INDEX(Tbl案件[破獲時間],MATCH(13,$S$100:$S$299,0)),"") | F23: =IFERROR(INDEX(Tbl案件[案件狀況],MATCH(13,$S$100:$S$299,0)),"") | G23: =IFERROR(INDEX(Tbl案件[偵辦進度],MATCH(13,$S$100:$S$299,0)),"") | H23: =IFERROR(INDEX(Tbl案件[承辦人],MATCH(13,$S$100:$S$299,0)),"") | I23: =IFERROR(INDEX(Tbl案件[備註],MATCH(13,$S$100:$S$299,0)),"")
A24: =IFERROR(INDEX(Tbl案件[編號],MATCH(14,$S$100:$S$299,0)),"") | B24: =IFERROR(INDEX(Tbl案件[案類],MATCH(14,$S$100:$S$299,0)),"") | C24: =IFERROR(INDEX(Tbl案件[發生時間],MATCH(14,$S$100:$S$299,0)),"") | D24: =IFERROR(INDEX(Tbl案件[發生地點],MATCH(14,$S$100:$S$299,0)),"") | E24: =IFERROR(INDEX(Tbl案件[破獲時間],MATCH(14,$S$100:$S$299,0)),"") | F24: =IFERROR(INDEX(Tbl案件[案件狀況],MATCH(14,$S$100:$S$299,0)),"") | G24: =IFERROR(INDEX(Tbl案件[偵辦進度],MATCH(14,$S$100:$S$299,0)),"") | H24: =IFERROR(INDEX(Tbl案件[承辦人],MATCH(14,$S$100:$S$299,0)),"") | I24: =IFERROR(INDEX(Tbl案件[備註],MATCH(14,$S$100:$S$299,0)),"")
A25: =IFERROR(INDEX(Tbl案件[編號],MATCH(15,$S$100:$S$299,0)),"") | B25: =IFERROR(INDEX(Tbl案件[案類],MATCH(15,$S$100:$S$299,0)),"") | C25: =IFERROR(INDEX(Tbl案件[發生時間],MATCH(15,$S$100:$S$299,0)),"") | D25: =IFERROR(INDEX(Tbl案件[發生地點],MATCH(15,$S$100:$S$299,0)),"") | E25: =IFERROR(INDEX(Tbl案件[破獲時間],MATCH(15,$S$100:$S$299,0)),"") | F25: =IFERROR(INDEX(Tbl案件[案件狀況],MATCH(15,$S$100:$S$299,0)),"") | G25: =IFERROR(INDEX(Tbl案件[偵辦進度],MATCH(15,$S$100:$S$299,0)),"") | H25: =IFERROR(INDEX(Tbl案件[承辦人],MATCH(15,$S$100:$S$299,0)),"") | I25: =IFERROR(INDEX(Tbl案件[備註],MATCH(15,$S$100:$S$299,0)),"")
A27: =" 🟡 已破獲未移送清單（"&IFERROR(COUNTIFS(Tbl案件[案件狀況],"已破獲未移送",Tbl案件[查獲管轄],"本轄",Tbl案件[歸屬年度],(YEAR(今日)-1911)),0)&" 件，最多顯示前 15 件，需催偵查隊）"
A28: 編號 | B28: 案類 | C28: 發生時間 | D28: 發生地 | E28: 破獲時間 | F28: 案件狀況 | G28: 偵辦進度 | H28: 承辦人 | I28: 備註
A29: =IFERROR(INDEX(Tbl案件[編號],MATCH(1,$U$100:$U$299,0)),"") | B29: =IFERROR(INDEX(Tbl案件[案類],MATCH(1,$U$100:$U$299,0)),"") | C29: =IFERROR(INDEX(Tbl案件[發生時間],MATCH(1,$U$100:$U$299,0)),"") | D29: =IFERROR(INDEX(Tbl案件[發生地點],MATCH(1,$U$100:$U$299,0)),"") | E29: =IFERROR(INDEX(Tbl案件[破獲時間],MATCH(1,$U$100:$U$299,0)),"") | F29: =IFERROR(INDEX(Tbl案件[案件狀況],MATCH(1,$U$100:$U$299,0)),"") | G29: =IFERROR(INDEX(Tbl案件[偵辦進度],MATCH(1,$U$100:$U$299,0)),"") | H29: =IFERROR(INDEX(Tbl案件[承辦人],MATCH(1,$U$100:$U$299,0)),"") | I29: =IFERROR(INDEX(Tbl案件[備註],MATCH(1,$U$100:$U$299,0)),"")
A30: =IFERROR(INDEX(Tbl案件[編號],MATCH(2,$U$100:$U$299,0)),"") | B30: =IFERROR(INDEX(Tbl案件[案類],MATCH(2,$U$100:$U$299,0)),"") | C30: =IFERROR(INDEX(Tbl案件[發生時間],MATCH(2,$U$100:$U$299,0)),"") | D30: =IFERROR(INDEX(Tbl案件[發生地點],MATCH(2,$U$100:$U$299,0)),"") | E30: =IFERROR(INDEX(Tbl案件[破獲時間],MATCH(2,$U$100:$U$299,0)),"") | F30: =IFERROR(INDEX(Tbl案件[案件狀況],MATCH(2,$U$100:$U$299,0)),"") | G30: =IFERROR(INDEX(Tbl案件[偵辦進度],MATCH(2,$U$100:$U$299,0)),"") | H30: =IFERROR(INDEX(Tbl案件[承辦人],MATCH(2,$U$100:$U$299,0)),"") | I30: =IFERROR(INDEX(Tbl案件[備註],MATCH(2,$U$100:$U$299,0)),"")
A31: =IFERROR(INDEX(Tbl案件[編號],MATCH(3,$U$100:$U$299,0)),"") | B31: =IFERROR(INDEX(Tbl案件[案類],MATCH(3,$U$100:$U$299,0)),"") | C31: =IFERROR(INDEX(Tbl案件[發生時間],MATCH(3,$U$100:$U$299,0)),"") | D31: =IFERROR(INDEX(Tbl案件[發生地點],MATCH(3,$U$100:$U$299,0)),"") | E31: =IFERROR(INDEX(Tbl案件[破獲時間],MATCH(3,$U$100:$U$299,0)),"") | F31: =IFERROR(INDEX(Tbl案件[案件狀況],MATCH(3,$U$100:$U$299,0)),"") | G31: =IFERROR(INDEX(Tbl案件[偵辦進度],MATCH(3,$U$100:$U$299,0)),"") | H31: =IFERROR(INDEX(Tbl案件[承辦人],MATCH(3,$U$100:$U$299,0)),"") | I31: =IFERROR(INDEX(Tbl案件[備註],MATCH(3,$U$100:$U$299,0)),"")
A32: =IFERROR(INDEX(Tbl案件[編號],MATCH(4,$U$100:$U$299,0)),"") | B32: =IFERROR(INDEX(Tbl案件[案類],MATCH(4,$U$100:$U$299,0)),"") | C32: =IFERROR(INDEX(Tbl案件[發生時間],MATCH(4,$U$100:$U$299,0)),"") | D32: =IFERROR(INDEX(Tbl案件[發生地點],MATCH(4,$U$100:$U$299,0)),"") | E32: =IFERROR(INDEX(Tbl案件[破獲時間],MATCH(4,$U$100:$U$299,0)),"") | F32: =IFERROR(INDEX(Tbl案件[案件狀況],MATCH(4,$U$100:$U$299,0)),"") | G32: =IFERROR(INDEX(Tbl案件[偵辦進度],MATCH(4,$U$100:$U$299,0)),"") | H32: =IFERROR(INDEX(Tbl案件[承辦人],MATCH(4,$U$100:$U$299,0)),"") | I32: =IFERROR(INDEX(Tbl案件[備註],MATCH(4,$U$100:$U$299,0)),"")
A33: =IFERROR(INDEX(Tbl案件[編號],MATCH(5,$U$100:$U$299,0)),"") | B33: =IFERROR(INDEX(Tbl案件[案類],MATCH(5,$U$100:$U$299,0)),"") | C33: =IFERROR(INDEX(Tbl案件[發生時間],MATCH(5,$U$100:$U$299,0)),"") | D33: =IFERROR(INDEX(Tbl案件[發生地點],MATCH(5,$U$100:$U$299,0)),"") | E33: =IFERROR(INDEX(Tbl案件[破獲時間],MATCH(5,$U$100:$U$299,0)),"") | F33: =IFERROR(INDEX(Tbl案件[案件狀況],MATCH(5,$U$100:$U$299,0)),"") | G33: =IFERROR(INDEX(Tbl案件[偵辦進度],MATCH(5,$U$100:$U$299,0)),"") | H33: =IFERROR(INDEX(Tbl案件[承辦人],MATCH(5,$U$100:$U$299,0)),"") | I33: =IFERROR(INDEX(Tbl案件[備註],MATCH(5,$U$100:$U$299,0)),"")
A34: =IFERROR(INDEX(Tbl案件[編號],MATCH(6,$U$100:$U$299,0)),"") | B34: =IFERROR(INDEX(Tbl案件[案類],MATCH(6,$U$100:$U$299,0)),"") | C34: =IFERROR(INDEX(Tbl案件[發生時間],MATCH(6,$U$100:$U$299,0)),"") | D34: =IFERROR(INDEX(Tbl案件[發生地點],MATCH(6,$U$100:$U$299,0)),"") | E34: =IFERROR(INDEX(Tbl案件[破獲時間],MATCH(6,$U$100:$U$299,0)),"") | F34: =IFERROR(INDEX(Tbl案件[案件狀況],MATCH(6,$U$100:$U$299,0)),"") | G34: =IFERROR(INDEX(Tbl案件[偵辦進度],MATCH(6,$U$100:$U$299,0)),"") | H34: =IFERROR(INDEX(Tbl案件[承辦人],MATCH(6,$U$100:$U$299,0)),"") | I34: =IFERROR(INDEX(Tbl案件[備註],MATCH(6,$U$100:$U$299,0)),"")
A35: =IFERROR(INDEX(Tbl案件[編號],MATCH(7,$U$100:$U$299,0)),"") | B35: =IFERROR(INDEX(Tbl案件[案類],MATCH(7,$U$100:$U$299,0)),"") | C35: =IFERROR(INDEX(Tbl案件[發生時間],MATCH(7,$U$100:$U$299,0)),"") | D35: =IFERROR(INDEX(Tbl案件[發生地點],MATCH(7,$U$100:$U$299,0)),"") | E35: =IFERROR(INDEX(Tbl案件[破獲時間],MATCH(7,$U$100:$U$299,0)),"") | F35: =IFERROR(INDEX(Tbl案件[案件狀況],MATCH(7,$U$100:$U$299,0)),"") | G35: =IFERROR(INDEX(Tbl案件[偵辦進度],MATCH(7,$U$100:$U$299,0)),"") | H35: =IFERROR(INDEX(Tbl案件[承辦人],MATCH(7,$U$100:$U$299,0)),"") | I35: =IFERROR(INDEX(Tbl案件[備註],MATCH(7,$U$100:$U$299,0)),"")
A36: =IFERROR(INDEX(Tbl案件[編號],MATCH(8,$U$100:$U$299,0)),"") | B36: =IFERROR(INDEX(Tbl案件[案類],MATCH(8,$U$100:$U$299,0)),"") | C36: =IFERROR(INDEX(Tbl案件[發生時間],MATCH(8,$U$100:$U$299,0)),"") | D36: =IFERROR(INDEX(Tbl案件[發生地點],MATCH(8,$U$100:$U$299,0)),"") | E36: =IFERROR(INDEX(Tbl案件[破獲時間],MATCH(8,$U$100:$U$299,0)),"") | F36: =IFERROR(INDEX(Tbl案件[案件狀況],MATCH(8,$U$100:$U$299,0)),"") | G36: =IFERROR(INDEX(Tbl案件[偵辦進度],MATCH(8,$U$100:$U$299,0)),"") | H36: =IFERROR(INDEX(Tbl案件[承辦人],MATCH(8,$U$100:$U$299,0)),"") | I36: =IFERROR(INDEX(Tbl案件[備註],MATCH(8,$U$100:$U$299,0)),"")
A37: =IFERROR(INDEX(Tbl案件[編號],MATCH(9,$U$100:$U$299,0)),"") | B37: =IFERROR(INDEX(Tbl案件[案類],MATCH(9,$U$100:$U$299,0)),"") | C37: =IFERROR(INDEX(Tbl案件[發生時間],MATCH(9,$U$100:$U$299,0)),"") | D37: =IFERROR(INDEX(Tbl案件[發生地點],MATCH(9,$U$100:$U$299,0)),"") | E37: =IFERROR(INDEX(Tbl案件[破獲時間],MATCH(9,$U$100:$U$299,0)),"") | F37: =IFERROR(INDEX(Tbl案件[案件狀況],MATCH(9,$U$100:$U$299,0)),"") | G37: =IFERROR(INDEX(Tbl案件[偵辦進度],MATCH(9,$U$100:$U$299,0)),"") | H37: =IFERROR(INDEX(Tbl案件[承辦人],MATCH(9,$U$100:$U$299,0)),"") | I37: =IFERROR(INDEX(Tbl案件[備註],MATCH(9,$U$100:$U$299,0)),"")
A38: =IFERROR(INDEX(Tbl案件[編號],MATCH(10,$U$100:$U$299,0)),"") | B38: =IFERROR(INDEX(Tbl案件[案類],MATCH(10,$U$100:$U$299,0)),"") | C38: =IFERROR(INDEX(Tbl案件[發生時間],MATCH(10,$U$100:$U$299,0)),"") | D38: =IFERROR(INDEX(Tbl案件[發生地點],MATCH(10,$U$100:$U$299,0)),"") | E38: =IFERROR(INDEX(Tbl案件[破獲時間],MATCH(10,$U$100:$U$299,0)),"") | F38: =IFERROR(INDEX(Tbl案件[案件狀況],MATCH(10,$U$100:$U$299,0)),"") | G38: =IFERROR(INDEX(Tbl案件[偵辦進度],MATCH(10,$U$100:$U$299,0)),"") | H38: =IFERROR(INDEX(Tbl案件[承辦人],MATCH(10,$U$100:$U$299,0)),"") | I38: =IFERROR(INDEX(Tbl案件[備註],MATCH(10,$U$100:$U$299,0)),"")
A39: =IFERROR(INDEX(Tbl案件[編號],MATCH(11,$U$100:$U$299,0)),"") | B39: =IFERROR(INDEX(Tbl案件[案類],MATCH(11,$U$100:$U$299,0)),"") | C39: =IFERROR(INDEX(Tbl案件[發生時間],MATCH(11,$U$100:$U$299,0)),"") | D39: =IFERROR(INDEX(Tbl案件[發生地點],MATCH(11,$U$100:$U$299,0)),"") | E39: =IFERROR(INDEX(Tbl案件[破獲時間],MATCH(11,$U$100:$U$299,0)),"") | F39: =IFERROR(INDEX(Tbl案件[案件狀況],MATCH(11,$U$100:$U$299,0)),"") | G39: =IFERROR(INDEX(Tbl案件[偵辦進度],MATCH(11,$U$100:$U$299,0)),"") | H39: =IFERROR(INDEX(Tbl案件[承辦人],MATCH(11,$U$100:$U$299,0)),"") | I39: =IFERROR(INDEX(Tbl案件[備註],MATCH(11,$U$100:$U$299,0)),"")
A40: =IFERROR(INDEX(Tbl案件[編號],MATCH(12,$U$100:$U$299,0)),"") | B40: =IFERROR(INDEX(Tbl案件[案類],MATCH(12,$U$100:$U$299,0)),"") | C40: =IFERROR(INDEX(Tbl案件[發生時間],MATCH(12,$U$100:$U$299,0)),"") | D40: =IFERROR(INDEX(Tbl案件[發生地點],MATCH(12,$U$100:$U$299,0)),"") | E40: =IFERROR(INDEX(Tbl案件[破獲時間],MATCH(12,$U$100:$U$299,0)),"") | F40: =IFERROR(INDEX(Tbl案件[案件狀況],MATCH(12,$U$100:$U$299,0)),"") | G40: =IFERROR(INDEX(Tbl案件[偵辦進度],MATCH(12,$U$100:$U$299,0)),"") | H40: =IFERROR(INDEX(Tbl案件[承辦人],MATCH(12,$U$100:$U$299,0)),"") | I40: =IFERROR(INDEX(Tbl案件[備註],MATCH(12,$U$100:$U$299,0)),"")
A41: =IFERROR(INDEX(Tbl案件[編號],MATCH(13,$U$100:$U$299,0)),"") | B41: =IFERROR(INDEX(Tbl案件[案類],MATCH(13,$U$100:$U$299,0)),"") | C41: =IFERROR(INDEX(Tbl案件[發生時間],MATCH(13,$U$100:$U$299,0)),"") | D41: =IFERROR(INDEX(Tbl案件[發生地點],MATCH(13,$U$100:$U$299,0)),"") | E41: =IFERROR(INDEX(Tbl案件[破獲時間],MATCH(13,$U$100:$U$299,0)),"") | F41: =IFERROR(INDEX(Tbl案件[案件狀況],MATCH(13,$U$100:$U$299,0)),"") | G41: =IFERROR(INDEX(Tbl案件[偵辦進度],MATCH(13,$U$100:$U$299,0)),"") | H41: =IFERROR(INDEX(Tbl案件[承辦人],MATCH(13,$U$100:$U$299,0)),"") | I41: =IFERROR(INDEX(Tbl案件[備註],MATCH(13,$U$100:$U$299,0)),"")
A42: =IFERROR(INDEX(Tbl案件[編號],MATCH(14,$U$100:$U$299,0)),"") | B42: =IFERROR(INDEX(Tbl案件[案類],MATCH(14,$U$100:$U$299,0)),"") | C42: =IFERROR(INDEX(Tbl案件[發生時間],MATCH(14,$U$100:$U$299,0)),"") | D42: =IFERROR(INDEX(Tbl案件[發生地點],MATCH(14,$U$100:$U$299,0)),"") | E42: =IFERROR(INDEX(Tbl案件[破獲時間],MATCH(14,$U$100:$U$299,0)),"") | F42: =IFERROR(INDEX(Tbl案件[案件狀況],MATCH(14,$U$100:$U$299,0)),"") | G42: =IFERROR(INDEX(Tbl案件[偵辦進度],MATCH(14,$U$100:$U$299,0)),"") | H42: =IFERROR(INDEX(Tbl案件[承辦人],MATCH(14,$U$100:$U$299,0)),"") | I42: =IFERROR(INDEX(Tbl案件[備註],MATCH(14,$U$100:$U$299,0)),"")
A43: =IFERROR(INDEX(Tbl案件[編號],MATCH(15,$U$100:$U$299,0)),"") | B43: =IFERROR(INDEX(Tbl案件[案類],MATCH(15,$U$100:$U$299,0)),"") | C43: =IFERROR(INDEX(Tbl案件[發生時間],MATCH(15,$U$100:$U$299,0)),"") | D43: =IFERROR(INDEX(Tbl案件[發生地點],MATCH(15,$U$100:$U$299,0)),"") | E43: =IFERROR(INDEX(Tbl案件[破獲時間],MATCH(15,$U$100:$U$299,0)),"") | F43: =IFERROR(INDEX(Tbl案件[案件狀況],MATCH(15,$U$100:$U$299,0)),"") | G43: =IFERROR(INDEX(Tbl案件[偵辦進度],MATCH(15,$U$100:$U$299,0)),"") | H43: =IFERROR(INDEX(Tbl案件[承辦人],MATCH(15,$U$100:$U$299,0)),"") | I43: =IFERROR(INDEX(Tbl案件[備註],MATCH(15,$U$100:$U$299,0)),"")
A45: ="© KKEVIN-LIN-2026-V2.0 ｜ v2.1 兩區段並呈（取代 v2 視圖下拉） ｜ 製表："&TEXT(今日,"e/mm/dd")
...

Sheet 發展中案件管制
A1: 📌 發展中案件管制（v2.1 加 承辦人 / 線索來源 / 重大性 三欄）
A2: 主表 9 欄（v43 6 欄 + v2.1 3 欄）+ 頂部三段狀態縮影 + 右側待轉案件候選（70/30 兩翼防呆）
A4: ⚡ 狀態縮影（v2.1 閾值改 7/30 日 — 更敏感）
A6: ="● 新進（≤"&新進閾值&" 日）" | C6: =3
A7: ="⚠ 偵辦中（"&(新進閾值+1)&"-"&老案閾值&" 日）" | C7: =4
A8: ="✕ 老案（>"&老案閾值&" 日）" | C8: =1
A10: ="🔧 閾值：新進 ≤ " & 新進閾值 & " 日 ｜ 老案 > " & 老案閾值 & " 日 ｜ 可在設定表 C 區調整"
A12: 📋 發展中案件主表（v43 6 欄 + v2.1 3 欄輸入 + 2 計算欄） | M12: 📌 待轉案件候選
A13: 編號 | B13: 案由 | C13: 進度 | D13: 執行時間 | E13: 查緝結果 | F13: 備註 | G13: 承辦人 | H13: 線索來源 | I13: 重大性 | J13: 距今 | K13: 狀態 | M13: # | N13: 案由 / 狀態 | O13: 操作
J14: 4 | K14: ● 綠 | M14: 003 | N14: 夜店毒品流通 已成熟 · 24 日 | O14: 轉案件
J15: 14 | K15: ⚠ 黃 | M15: 005 | N15: 外勞集資詐騙 已成熟 · 20 日 | O15: 轉案件
J16: 24 | K16: ⚠ 黃 | M16: 004 | N16: ○○街頭聚賭 老案逾 30 · 36 日 | O16: 評估簽結
J17: 36 | K17: ✕ 紅 | M17: ✏ 偵查佐評估後：「轉案件」者複製欄位 → 貼到頁 5
J18: 20 | K18: ⚠ 黃

Sheet 毒品調驗人口管制
A1: 💊 毒品調驗人口管制（v43 9 欄 + v2.2 加最後到驗日精確 30 日逾期）
A2: =" "&警察局名稱&" · "&分局名稱&" · "&派出所名稱&" ｜ 中華民國 "&(YEAR(今日)-1911)&" 年累計（截至 "&TEXT(今日,"mm/dd")&"）｜ 業務規則：通緝/強採/在監 算到驗 ｜ 距今 > 30 日紅燈"
A4: 💡 主表 9 欄 v43 不動 + 最後到驗日（J）。狀態燈/候選由公式自動驅動 （含距今 > 30 日精確判斷）。毒調率目標可在設定表 C 區調整。
A6: 📊 頂部狀態縮影 + 毒調率（公式自動） | P6: ⚠ 應強採候選清單
A8: 👥 列管總數 | C8: ● 已到驗（含 4 種） | E8: ● 未到驗 | G8: ⚠ 應強採候選
A9: =COUNTA(Tbl毒調[姓名]) | C9: =SUM(Tbl毒調[是否到驗]) | E9: =COUNTA(Tbl毒調[姓名])-SUM(Tbl毒調[是否到驗])-COUNTIF(Tbl毒調[狀態燈],"*結束*") | G9: =SUM(Tbl毒調[候選旗標])
A11: ="毒調率：" & TEXT(IFERROR(SUM(Tbl毒調[是否到驗])/COUNTA(Tbl毒調[姓名]),0),"0.0%")&" ｜ 目標 ≥"&TEXT(毒調率目標,"0%")&" ｜ 狀態："&IF(IFERROR(SUM(Tbl毒調[是否到驗])/COUNTA(Tbl毒調[姓名]),0)>=毒調率目標,"● 達標","● 未達標")
A12: =REPT("█",MIN(20,ROUND(IFERROR(SUM(Tbl毒調[是否到驗])/COUNTA(Tbl毒調[姓名]),0)*20,0)))&REPT("░",20-MIN(20,ROUND(IFERROR(SUM(Tbl毒調[是否到驗])/COUNTA(Tbl毒調[姓名]),0)*20,0)))
A13: 📋 列管人口主表（Tbl毒調 9 欄維持 v43 不動 + 3 計算欄隱藏）
A14: 編號 | B14: 姓名 | C14: 身分證 | D14: 性別 | E14: 住所 | F14: 聯繫 | G14: 通緝 | H14: 管制情形 | I14: 備註 | J14: 最後到驗日 | K14: 距今天數 | L14: 是否到驗 | M14: 狀態燈 | N14: 候選旗標 | P14: 編號 | Q14: 姓名 | R14: 管制狀態 | S14: 操作建議
K15: =IFERROR(IF([@最後到驗日]="","",今日-[@最後到驗日]),"") | L15: =IFERROR(IF([@管制情形]="",0,IF(OR(SUMPRODUCT(--ISNUMBER(SEARCH({"已驗","已到驗","通緝","強採","在監"},[@管制情形])))>0,AND(ISNUMBER([@距今天數]),[@距今天數]<=30)),1,0)),0) | M15: =IFERROR(IF([@管制情形]="","○ 未填",IF(ISNUMBER(SEARCH("解除",[@管制情形])),"○ 結束",IF(AND(ISNUMBER([@距今天數]),[@距今天數]>30),"● 紅",IF([@是否到驗]=1,"● 綠","⚠ 黃")))),"") | N15: =IFERROR(IF(OR(ISNUMBER(SEARCH("未到驗",[@管制情形])),AND(ISNUMBER([@距今天數]),[@距今天數]>30)),1,0),0) | P15: =IFERROR(INDEX(Tbl毒調[編號],MATCH(1,$V$100:$V$169,0)),"") | Q15: =IFERROR(INDEX(Tbl毒調[姓名],MATCH(1,$V$100:$V$169,0)),"") | R15: =IFERROR(INDEX(Tbl毒調[管制情形],MATCH(1,$V$100:$V$169,0)),"") | S15: =IF(P15="","","聲請強採書（30 日內）")
